2025-08-02 15:26:22,114 - src.pipeline.classifier - INFO - No saved model found, will need to train
2025-08-02 15:26:22,116 - elastic_transport.transport - INFO - HEAD http://localhost:9200/ [status:N/A duration:0.001s]
2025-08-02 15:26:22,116 - elastic_transport.node_pool - WARNING - Node <Urllib3HttpNode(http://localhost:9200)> has failed for 1 times in a row, putting on 1 second timeout
2025-08-02 15:26:22,116 - elastic_transport.transport - WARNING - Retrying request after failure (attempt 0 of 3)
Traceback (most recent call last):
  File "/usr/lib/python3/dist-packages/urllib3/connection.py", line 203, in _new_conn
    sock = connection.create_connection(
           ^^^^^^^^^^^^^^^^^^^^^^^^^^^^^
  File "/usr/lib/python3/dist-packages/urllib3/util/connection.py", line 85, in create_connection
    raise err
  File "/usr/lib/python3/dist-packages/urllib3/util/connection.py", line 73, in create_connection
    sock.connect(sa)
ConnectionRefusedError: [Errno 111] Connection refused

The above exception was the direct cause of the following exception:

Traceback (most recent call last):
  File "/home/runner/.local/lib/python3.12/site-packages/elastic_transport/_node/_http_urllib3.py", line 167, in perform_request
    response = self.pool.urlopen(
               ^^^^^^^^^^^^^^^^^^
  File "/usr/lib/python3/dist-packages/urllib3/connectionpool.py", line 845, in urlopen
    retries = retries.increment(
              ^^^^^^^^^^^^^^^^^^
  File "/usr/lib/python3/dist-packages/urllib3/util/retry.py", line 447, in increment
    raise reraise(type(error), error, _stacktrace)
          ^^^^^^^^^^^^^^^^^^^^^^^^^^^^^^^^^^^^^^^^
  File "/usr/lib/python3/dist-packages/urllib3/util/util.py", line 39, in reraise
    raise value
  File "/usr/lib/python3/dist-packages/urllib3/connectionpool.py", line 791, in urlopen
    response = self._make_request(
               ^^^^^^^^^^^^^^^^^^^
  File "/usr/lib/python3/dist-packages/urllib3/connectionpool.py", line 497, in _make_request
    conn.request(
  File "/usr/lib/python3/dist-packages/urllib3/connection.py", line 395, in request
    self.endheaders()
  File "/usr/lib/python3.12/http/client.py", line 1331, in endheaders
    self._send_output(message_body, encode_chunked=encode_chunked)
  File "/usr/lib/python3.12/http/client.py", line 1091, in _send_output
    self.send(msg)
  File "/usr/lib/python3.12/http/client.py", line 1035, in send
    self.connect()
  File "/usr/lib/python3/dist-packages/urllib3/connection.py", line 243, in connect
    self.sock = self._new_conn()
                ^^^^^^^^^^^^^^^^
  File "/usr/lib/python3/dist-packages/urllib3/connection.py", line 218, in _new_conn
    raise NewConnectionError(
urllib3.exceptions.NewConnectionError: <urllib3.connection.HTTPConnection object at 0x7f1b3826d4c0>: Failed to establish a new connection: [Errno 111] Connection refused

The above exception was the direct cause of the following exception:

Traceback (most recent call last):
  File "/home/runner/.local/lib/python3.12/site-packages/elastic_transport/_transport.py", line 344, in perform_request
    resp = node.perform_request(
           ^^^^^^^^^^^^^^^^^^^^^
  File "/home/runner/.local/lib/python3.12/site-packages/elastic_transport/_node/_http_urllib3.py", line 202, in perform_request
    raise err from e
elastic_transport.ConnectionError: Connection error caused by: NewConnectionError(<urllib3.connection.HTTPConnection object at 0x7f1b3826d4c0>: Failed to establish a new connection: [Errno 111] Connection refused)
2025-08-02 15:26:22,121 - elastic_transport.transport - INFO - HEAD http://localhost:9200/ [status:N/A duration:0.000s]
2025-08-02 15:26:22,121 - elastic_transport.node_pool - WARNING - Node <Urllib3HttpNode(http://localhost:9200)> has failed for 2 times in a row, putting on 2 second timeout
2025-08-02 15:26:22,121 - elastic_transport.transport - WARNING - Retrying request after failure (attempt 1 of 3)
Traceback (most recent call last):
  File "/usr/lib/python3/dist-packages/urllib3/connection.py", line 203, in _new_conn
    sock = connection.create_connection(
           ^^^^^^^^^^^^^^^^^^^^^^^^^^^^^
  File "/usr/lib/python3/dist-packages/urllib3/util/connection.py", line 85, in create_connection
    raise err
  File "/usr/lib/python3/dist-packages/urllib3/util/connection.py", line 73, in create_connection
    sock.connect(sa)
ConnectionRefusedError: [Errno 111] Connection refused

The above exception was the direct cause of the following exception:

Traceback (most recent call last):
  File "/home/runner/.local/lib/python3.12/site-packages/elastic_transport/_node/_http_urllib3.py", line 167, in perform_request
    response = self.pool.urlopen(
               ^^^^^^^^^^^^^^^^^^
  File "/usr/lib/python3/dist-packages/urllib3/connectionpool.py", line 845, in urlopen
    retries = retries.increment(
              ^^^^^^^^^^^^^^^^^^
  File "/usr/lib/python3/dist-packages/urllib3/util/retry.py", line 447, in increment
    raise reraise(type(error), error, _stacktrace)
          ^^^^^^^^^^^^^^^^^^^^^^^^^^^^^^^^^^^^^^^^
  File "/usr/lib/python3/dist-packages/urllib3/util/util.py", line 39, in reraise
    raise value
  File "/usr/lib/python3/dist-packages/urllib3/connectionpool.py", line 791, in urlopen
    response = self._make_request(
               ^^^^^^^^^^^^^^^^^^^
  File "/usr/lib/python3/dist-packages/urllib3/connectionpool.py", line 497, in _make_request
    conn.request(
  File "/usr/lib/python3/dist-packages/urllib3/connection.py", line 395, in request
    self.endheaders()
  File "/usr/lib/python3.12/http/client.py", line 1331, in endheaders
    self._send_output(message_body, encode_chunked=encode_chunked)
  File "/usr/lib/python3.12/http/client.py", line 1091, in _send_output
    self.send(msg)
  File "/usr/lib/python3.12/http/client.py", line 1035, in send
    self.connect()
  File "/usr/lib/python3/dist-packages/urllib3/connection.py", line 243, in connect
    self.sock = self._new_conn()
                ^^^^^^^^^^^^^^^^
  File "/usr/lib/python3/dist-packages/urllib3/connection.py", line 218, in _new_conn
    raise NewConnectionError(
urllib3.exceptions.NewConnectionError: <urllib3.connection.HTTPConnection object at 0x7f1b37879f70>: Failed to establish a new connection: [Errno 111] Connection refused

The above exception was the direct cause of the following exception:

Traceback (most recent call last):
  File "/home/runner/.local/lib/python3.12/site-packages/elastic_transport/_transport.py", line 344, in perform_request
    resp = node.perform_request(
           ^^^^^^^^^^^^^^^^^^^^^
  File "/home/runner/.local/lib/python3.12/site-packages/elastic_transport/_node/_http_urllib3.py", line 202, in perform_request
    raise err from e
elastic_transport.ConnectionError: Connection error caused by: NewConnectionError(<urllib3.connection.HTTPConnection object at 0x7f1b37879f70>: Failed to establish a new connection: [Errno 111] Connection refused)
2025-08-02 15:26:22,122 - elastic_transport.transport - INFO - HEAD http://localhost:9200/ [status:N/A duration:0.000s]
2025-08-02 15:26:22,123 - elastic_transport.node_pool - WARNING - Node <Urllib3HttpNode(http://localhost:9200)> has failed for 3 times in a row, putting on 4 second timeout
2025-08-02 15:26:22,123 - elastic_transport.transport - WARNING - Retrying request after failure (attempt 2 of 3)
Traceback (most recent call last):
  File "/usr/lib/python3/dist-packages/urllib3/connection.py", line 203, in _new_conn
    sock = connection.create_connection(
           ^^^^^^^^^^^^^^^^^^^^^^^^^^^^^
  File "/usr/lib/python3/dist-packages/urllib3/util/connection.py", line 85, in create_connection
    raise err
  File "/usr/lib/python3/dist-packages/urllib3/util/connection.py", line 73, in create_connection
    sock.connect(sa)
ConnectionRefusedError: [Errno 111] Connection refused

The above exception was the direct cause of the following exception:

Traceback (most recent call last):
  File "/home/runner/.local/lib/python3.12/site-packages/elastic_transport/_node/_http_urllib3.py", line 167, in perform_request
    response = self.pool.urlopen(
               ^^^^^^^^^^^^^^^^^^
  File "/usr/lib/python3/dist-packages/urllib3/connectionpool.py", line 845, in urlopen
    retries = retries.increment(
              ^^^^^^^^^^^^^^^^^^
  File "/usr/lib/python3/dist-packages/urllib3/util/retry.py", line 447, in increment
    raise reraise(type(error), error, _stacktrace)
          ^^^^^^^^^^^^^^^^^^^^^^^^^^^^^^^^^^^^^^^^
  File "/usr/lib/python3/dist-packages/urllib3/util/util.py", line 39, in reraise
    raise value
  File "/usr/lib/python3/dist-packages/urllib3/connectionpool.py", line 791, in urlopen
    response = self._make_request(
               ^^^^^^^^^^^^^^^^^^^
  File "/usr/lib/python3/dist-packages/urllib3/connectionpool.py", line 497, in _make_request
    conn.request(
  File "/usr/lib/python3/dist-packages/urllib3/connection.py", line 395, in request
    self.endheaders()
  File "/usr/lib/python3.12/http/client.py", line 1331, in endheaders
    self._send_output(message_body, encode_chunked=encode_chunked)
  File "/usr/lib/python3.12/http/client.py", line 1091, in _send_output
    self.send(msg)
  File "/usr/lib/python3.12/http/client.py", line 1035, in send
    self.connect()
  File "/usr/lib/python3/dist-packages/urllib3/connection.py", line 243, in connect
    self.sock = self._new_conn()
                ^^^^^^^^^^^^^^^^
  File "/usr/lib/python3/dist-packages/urllib3/connection.py", line 218, in _new_conn
    raise NewConnectionError(
urllib3.exceptions.NewConnectionError: <urllib3.connection.HTTPConnection object at 0x7f1b38c9aff0>: Failed to establish a new connection: [Errno 111] Connection refused

The above exception was the direct cause of the following exception:

Traceback (most recent call last):
  File "/home/runner/.local/lib/python3.12/site-packages/elastic_transport/_transport.py", line 344, in perform_request
    resp = node.perform_request(
           ^^^^^^^^^^^^^^^^^^^^^
  File "/home/runner/.local/lib/python3.12/site-packages/elastic_transport/_node/_http_urllib3.py", line 202, in perform_request
    raise err from e
elastic_transport.ConnectionError: Connection error caused by: NewConnectionError(<urllib3.connection.HTTPConnection object at 0x7f1b38c9aff0>: Failed to establish a new connection: [Errno 111] Connection refused)
2025-08-02 15:26:22,124 - elastic_transport.transport - INFO - HEAD http://localhost:9200/ [status:N/A duration:0.000s]
2025-08-02 15:26:22,124 - elastic_transport.node_pool - WARNING - Node <Urllib3HttpNode(http://localhost:9200)> has failed for 4 times in a row, putting on 8 second timeout
2025-08-02 15:26:22,124 - src.pipeline.elasticsearch_indexer - ERROR - Cannot connect to Elasticsearch at http://localhost:9200
2025-08-02 15:26:22,124 - src.pipeline.pipeline_processor - INFO - Pipeline processor initialized
2025-08-02 15:26:22,124 - src.pipeline.pipeline_processor - INFO - Pipeline manager initialized
2025-08-02 15:26:22,124 - src.pipeline.pipeline_processor - INFO - Starting PDF processing pipeline...
2025-08-02 15:26:22,125 - src.pipeline.ocr_processor - ERROR - Tesseract installation test failed: tesseract is not installed or it's not in your PATH. See README file for more information.
2025-08-02 15:26:22,126 - elastic_transport.transport - INFO - HEAD http://localhost:9200/ [status:N/A duration:0.000s]
2025-08-02 15:26:22,126 - elastic_transport.node_pool - WARNING - Node <Urllib3HttpNode(http://localhost:9200)> has failed for 5 times in a row, putting on 16 second timeout
2025-08-02 15:26:22,126 - elastic_transport.transport - WARNING - Retrying request after failure (attempt 0 of 3)
Traceback (most recent call last):
  File "/usr/lib/python3/dist-packages/urllib3/connection.py", line 203, in _new_conn
    sock = connection.create_connection(
           ^^^^^^^^^^^^^^^^^^^^^^^^^^^^^
  File "/usr/lib/python3/dist-packages/urllib3/util/connection.py", line 85, in create_connection
    raise err
  File "/usr/lib/python3/dist-packages/urllib3/util/connection.py", line 73, in create_connection
    sock.connect(sa)
ConnectionRefusedError: [Errno 111] Connection refused

The above exception was the direct cause of the following exception:

Traceback (most recent call last):
  File "/home/runner/.local/lib/python3.12/site-packages/elastic_transport/_node/_http_urllib3.py", line 167, in perform_request
    response = self.pool.urlopen(
               ^^^^^^^^^^^^^^^^^^
  File "/usr/lib/python3/dist-packages/urllib3/connectionpool.py", line 845, in urlopen
    retries = retries.increment(
              ^^^^^^^^^^^^^^^^^^
  File "/usr/lib/python3/dist-packages/urllib3/util/retry.py", line 447, in increment
    raise reraise(type(error), error, _stacktrace)
          ^^^^^^^^^^^^^^^^^^^^^^^^^^^^^^^^^^^^^^^^
  File "/usr/lib/python3/dist-packages/urllib3/util/util.py", line 39, in reraise
    raise value
  File "/usr/lib/python3/dist-packages/urllib3/connectionpool.py", line 791, in urlopen
    response = self._make_request(
               ^^^^^^^^^^^^^^^^^^^
  File "/usr/lib/python3/dist-packages/urllib3/connectionpool.py", line 497, in _make_request
    conn.request(
  File "/usr/lib/python3/dist-packages/urllib3/connection.py", line 395, in request
    self.endheaders()
  File "/usr/lib/python3.12/http/client.py", line 1331, in endheaders
    self._send_output(message_body, encode_chunked=encode_chunked)
  File "/usr/lib/python3.12/http/client.py", line 1091, in _send_output
    self.send(msg)
  File "/usr/lib/python3.12/http/client.py", line 1035, in send
    self.connect()
  File "/usr/lib/python3/dist-packages/urllib3/connection.py", line 243, in connect
    self.sock = self._new_conn()
                ^^^^^^^^^^^^^^^^
  File "/usr/lib/python3/dist-packages/urllib3/connection.py", line 218, in _new_conn
    raise NewConnectionError(
urllib3.exceptions.NewConnectionError: <urllib3.connection.HTTPConnection object at 0x7f1b377d5400>: Failed to establish a new connection: [Errno 111] Connection refused

The above exception was the direct cause of the following exception:

Traceback (most recent call last):
  File "/home/runner/.local/lib/python3.12/site-packages/elastic_transport/_transport.py", line 344, in perform_request
    resp = node.perform_request(
           ^^^^^^^^^^^^^^^^^^^^^
  File "/home/runner/.local/lib/python3.12/site-packages/elastic_transport/_node/_http_urllib3.py", line 202, in perform_request
    raise err from e
elastic_transport.ConnectionError: Connection error caused by: NewConnectionError(<urllib3.connection.HTTPConnection object at 0x7f1b377d5400>: Failed to establish a new connection: [Errno 111] Connection refused)
2025-08-02 15:26:22,127 - elastic_transport.transport - INFO - HEAD http://localhost:9200/ [status:N/A duration:0.000s]
2025-08-02 15:26:22,127 - elastic_transport.node_pool - WARNING - Node <Urllib3HttpNode(http://localhost:9200)> has failed for 6 times in a row, putting on 30 second timeout
2025-08-02 15:26:22,127 - elastic_transport.transport - WARNING - Retrying request after failure (attempt 1 of 3)
Traceback (most recent call last):
  File "/usr/lib/python3/dist-packages/urllib3/connection.py", line 203, in _new_conn
    sock = connection.create_connection(
           ^^^^^^^^^^^^^^^^^^^^^^^^^^^^^
  File "/usr/lib/python3/dist-packages/urllib3/util/connection.py", line 85, in create_connection
    raise err
  File "/usr/lib/python3/dist-packages/urllib3/util/connection.py", line 73, in create_connection
    sock.connect(sa)
ConnectionRefusedError: [Errno 111] Connection refused

The above exception was the direct cause of the following exception:

Traceback (most recent call last):
  File "/home/runner/.local/lib/python3.12/site-packages/elastic_transport/_node/_http_urllib3.py", line 167, in perform_request
    response = self.pool.urlopen(
               ^^^^^^^^^^^^^^^^^^
  File "/usr/lib/python3/dist-packages/urllib3/connectionpool.py", line 845, in urlopen
    retries = retries.increment(
              ^^^^^^^^^^^^^^^^^^
  File "/usr/lib/python3/dist-packages/urllib3/util/retry.py", line 447, in increment
    raise reraise(type(error), error, _stacktrace)
          ^^^^^^^^^^^^^^^^^^^^^^^^^^^^^^^^^^^^^^^^
  File "/usr/lib/python3/dist-packages/urllib3/util/util.py", line 39, in reraise
    raise value
  File "/usr/lib/python3/dist-packages/urllib3/connectionpool.py", line 791, in urlopen
    response = self._make_request(
               ^^^^^^^^^^^^^^^^^^^
  File "/usr/lib/python3/dist-packages/urllib3/connectionpool.py", line 497, in _make_request
    conn.request(
  File "/usr/lib/python3/dist-packages/urllib3/connection.py", line 395, in request
    self.endheaders()
  File "/usr/lib/python3.12/http/client.py", line 1331, in endheaders
    self._send_output(message_body, encode_chunked=encode_chunked)
  File "/usr/lib/python3.12/http/client.py", line 1091, in _send_output
    self.send(msg)
  File "/usr/lib/python3.12/http/client.py", line 1035, in send
    self.connect()
  File "/usr/lib/python3/dist-packages/urllib3/connection.py", line 243, in connect
    self.sock = self._new_conn()
                ^^^^^^^^^^^^^^^^
  File "/usr/lib/python3/dist-packages/urllib3/connection.py", line 218, in _new_conn
    raise NewConnectionError(
urllib3.exceptions.NewConnectionError: <urllib3.connection.HTTPConnection object at 0x7f1b377d5ac0>: Failed to establish a new connection: [Errno 111] Connection refused

The above exception was the direct cause of the following exception:

Traceback (most recent call last):
  File "/home/runner/.local/lib/python3.12/site-packages/elastic_transport/_transport.py", line 344, in perform_request
    resp = node.perform_request(
           ^^^^^^^^^^^^^^^^^^^^^
  File "/home/runner/.local/lib/python3.12/site-packages/elastic_transport/_node/_http_urllib3.py", line 202, in perform_request
    raise err from e
elastic_transport.ConnectionError: Connection error caused by: NewConnectionError(<urllib3.connection.HTTPConnection object at 0x7f1b377d5ac0>: Failed to establish a new connection: [Errno 111] Connection refused)
2025-08-02 15:26:22,129 - elastic_transport.transport - INFO - HEAD http://localhost:9200/ [status:N/A duration:0.000s]
2025-08-02 15:26:22,129 - elastic_transport.node_pool - WARNING - Node <Urllib3HttpNode(http://localhost:9200)> has failed for 7 times in a row, putting on 30 second timeout
2025-08-02 15:26:22,129 - elastic_transport.transport - WARNING - Retrying request after failure (attempt 2 of 3)
Traceback (most recent call last):
  File "/usr/lib/python3/dist-packages/urllib3/connection.py", line 203, in _new_conn
    sock = connection.create_connection(
           ^^^^^^^^^^^^^^^^^^^^^^^^^^^^^
  File "/usr/lib/python3/dist-packages/urllib3/util/connection.py", line 85, in create_connection
    raise err
  File "/usr/lib/python3/dist-packages/urllib3/util/connection.py", line 73, in create_connection
    sock.connect(sa)
ConnectionRefusedError: [Errno 111] Connection refused

The above exception was the direct cause of the following exception:

Traceback (most recent call last):
  File "/home/runner/.local/lib/python3.12/site-packages/elastic_transport/_node/_http_urllib3.py", line 167, in perform_request
    response = self.pool.urlopen(
               ^^^^^^^^^^^^^^^^^^
  File "/usr/lib/python3/dist-packages/urllib3/connectionpool.py", line 845, in urlopen
    retries = retries.increment(
              ^^^^^^^^^^^^^^^^^^
  File "/usr/lib/python3/dist-packages/urllib3/util/retry.py", line 447, in increment
    raise reraise(type(error), error, _stacktrace)
          ^^^^^^^^^^^^^^^^^^^^^^^^^^^^^^^^^^^^^^^^
  File "/usr/lib/python3/dist-packages/urllib3/util/util.py", line 39, in reraise
    raise value
  File "/usr/lib/python3/dist-packages/urllib3/connectionpool.py", line 791, in urlopen
    response = self._make_request(
               ^^^^^^^^^^^^^^^^^^^
  File "/usr/lib/python3/dist-packages/urllib3/connectionpool.py", line 497, in _make_request
    conn.request(
  File "/usr/lib/python3/dist-packages/urllib3/connection.py", line 395, in request
    self.endheaders()
  File "/usr/lib/python3.12/http/client.py", line 1331, in endheaders
    self._send_output(message_body, encode_chunked=encode_chunked)
  File "/usr/lib/python3.12/http/client.py", line 1091, in _send_output
    self.send(msg)
  File "/usr/lib/python3.12/http/client.py", line 1035, in send
    self.connect()
  File "/usr/lib/python3/dist-packages/urllib3/connection.py", line 243, in connect
    self.sock = self._new_conn()
                ^^^^^^^^^^^^^^^^
  File "/usr/lib/python3/dist-packages/urllib3/connection.py", line 218, in _new_conn
    raise NewConnectionError(
urllib3.exceptions.NewConnectionError: <urllib3.connection.HTTPConnection object at 0x7f1b377d58e0>: Failed to establish a new connection: [Errno 111] Connection refused

The above exception was the direct cause of the following exception:

Traceback (most recent call last):
  File "/home/runner/.local/lib/python3.12/site-packages/elastic_transport/_transport.py", line 344, in perform_request
    resp = node.perform_request(
           ^^^^^^^^^^^^^^^^^^^^^
  File "/home/runner/.local/lib/python3.12/site-packages/elastic_transport/_node/_http_urllib3.py", line 202, in perform_request
    raise err from e
elastic_transport.ConnectionError: Connection error caused by: NewConnectionError(<urllib3.connection.HTTPConnection object at 0x7f1b377d58e0>: Failed to establish a new connection: [Errno 111] Connection refused)
2025-08-02 15:26:22,130 - elastic_transport.transport - INFO - HEAD http://localhost:9200/ [status:N/A duration:0.000s]
2025-08-02 15:26:22,130 - elastic_transport.node_pool - WARNING - Node <Urllib3HttpNode(http://localhost:9200)> has failed for 8 times in a row, putting on 30 second timeout
2025-08-02 15:26:22,130 - src.pipeline.pipeline_processor - INFO - ✓ format_detector: OK
2025-08-02 15:26:22,130 - src.pipeline.pipeline_processor - WARNING - ✗ ocr_processor: tesseract is not installed or it's not in your PATH. See README file for more information.
2025-08-02 15:26:22,130 - src.pipeline.pipeline_processor - INFO - ✓ text_extractor: OK
2025-08-02 15:26:22,130 - src.pipeline.pipeline_processor - INFO - ✓ classifier: OK
2025-08-02 15:26:22,130 - src.pipeline.pipeline_processor - WARNING - ✗ elasticsearch: Cannot reach Elasticsearch
2025-08-02 15:26:22,130 - src.pipeline.pipeline_processor - INFO - Setting up default classifier with sample data...
2025-08-02 15:26:22,132 - src.pipeline.classifier - ERROR - Error training model: The test_size = 6 should be greater or equal to the number of classes = 10
2025-08-02 15:26:22,133 - src.pipeline.pipeline_processor - ERROR - Failed to train default classifier: The test_size = 6 should be greater or equal to the number of classes = 10
2025-08-02 15:26:22,133 - src.pipeline.pipeline_processor - INFO - Pipeline system started successfully
2025-08-02 15:26:22,133 - src.pipeline.ocr_processor - ERROR - Tesseract installation test failed: tesseract is not installed or it's not in your PATH. See README file for more information.
2025-08-02 15:26:22,134 - elastic_transport.transport - INFO - HEAD http://localhost:9200/ [status:N/A duration:0.000s]
2025-08-02 15:26:22,134 - elastic_transport.node_pool - WARNING - Node <Urllib3HttpNode(http://localhost:9200)> has failed for 9 times in a row, putting on 30 second timeout
2025-08-02 15:26:22,134 - elastic_transport.transport - WARNING - Retrying request after failure (attempt 0 of 3)
Traceback (most recent call last):
  File "/usr/lib/python3/dist-packages/urllib3/connection.py", line 203, in _new_conn
    sock = connection.create_connection(
           ^^^^^^^^^^^^^^^^^^^^^^^^^^^^^
  File "/usr/lib/python3/dist-packages/urllib3/util/connection.py", line 85, in create_connection
    raise err
  File "/usr/lib/python3/dist-packages/urllib3/util/connection.py", line 73, in create_connection
    sock.connect(sa)
ConnectionRefusedError: [Errno 111] Connection refused

The above exception was the direct cause of the following exception:

Traceback (most recent call last):
  File "/home/runner/.local/lib/python3.12/site-packages/elastic_transport/_node/_http_urllib3.py", line 167, in perform_request
    response = self.pool.urlopen(
               ^^^^^^^^^^^^^^^^^^
  File "/usr/lib/python3/dist-packages/urllib3/connectionpool.py", line 845, in urlopen
    retries = retries.increment(
              ^^^^^^^^^^^^^^^^^^
  File "/usr/lib/python3/dist-packages/urllib3/util/retry.py", line 447, in increment
    raise reraise(type(error), error, _stacktrace)
          ^^^^^^^^^^^^^^^^^^^^^^^^^^^^^^^^^^^^^^^^
  File "/usr/lib/python3/dist-packages/urllib3/util/util.py", line 39, in reraise
    raise value
  File "/usr/lib/python3/dist-packages/urllib3/connectionpool.py", line 791, in urlopen
    response = self._make_request(
               ^^^^^^^^^^^^^^^^^^^
  File "/usr/lib/python3/dist-packages/urllib3/connectionpool.py", line 497, in _make_request
    conn.request(
  File "/usr/lib/python3/dist-packages/urllib3/connection.py", line 395, in request
    self.endheaders()
  File "/usr/lib/python3.12/http/client.py", line 1331, in endheaders
    self._send_output(message_body, encode_chunked=encode_chunked)
  File "/usr/lib/python3.12/http/client.py", line 1091, in _send_output
    self.send(msg)
  File "/usr/lib/python3.12/http/client.py", line 1035, in send
    self.connect()
  File "/usr/lib/python3/dist-packages/urllib3/connection.py", line 243, in connect
    self.sock = self._new_conn()
                ^^^^^^^^^^^^^^^^
  File "/usr/lib/python3/dist-packages/urllib3/connection.py", line 218, in _new_conn
    raise NewConnectionError(
urllib3.exceptions.NewConnectionError: <urllib3.connection.HTTPConnection object at 0x7f1b381f04a0>: Failed to establish a new connection: [Errno 111] Connection refused

The above exception was the direct cause of the following exception:

Traceback (most recent call last):
  File "/home/runner/.local/lib/python3.12/site-packages/elastic_transport/_transport.py", line 344, in perform_request
    resp = node.perform_request(
           ^^^^^^^^^^^^^^^^^^^^^
  File "/home/runner/.local/lib/python3.12/site-packages/elastic_transport/_node/_http_urllib3.py", line 202, in perform_request
    raise err from e
elastic_transport.ConnectionError: Connection error caused by: NewConnectionError(<urllib3.connection.HTTPConnection object at 0x7f1b381f04a0>: Failed to establish a new connection: [Errno 111] Connection refused)
2025-08-02 15:26:22,135 - elastic_transport.transport - INFO - HEAD http://localhost:9200/ [status:N/A duration:0.000s]
2025-08-02 15:26:22,135 - elastic_transport.node_pool - WARNING - Node <Urllib3HttpNode(http://localhost:9200)> has failed for 10 times in a row, putting on 30 second timeout
2025-08-02 15:26:22,135 - elastic_transport.transport - WARNING - Retrying request after failure (attempt 1 of 3)
Traceback (most recent call last):
  File "/usr/lib/python3/dist-packages/urllib3/connection.py", line 203, in _new_conn
    sock = connection.create_connection(
           ^^^^^^^^^^^^^^^^^^^^^^^^^^^^^
  File "/usr/lib/python3/dist-packages/urllib3/util/connection.py", line 85, in create_connection
    raise err
  File "/usr/lib/python3/dist-packages/urllib3/util/connection.py", line 73, in create_connection
    sock.connect(sa)
ConnectionRefusedError: [Errno 111] Connection refused

The above exception was the direct cause of the following exception:

Traceback (most recent call last):
  File "/home/runner/.local/lib/python3.12/site-packages/elastic_transport/_node/_http_urllib3.py", line 167, in perform_request
    response = self.pool.urlopen(
               ^^^^^^^^^^^^^^^^^^
  File "/usr/lib/python3/dist-packages/urllib3/connectionpool.py", line 845, in urlopen
    retries = retries.increment(
              ^^^^^^^^^^^^^^^^^^
  File "/usr/lib/python3/dist-packages/urllib3/util/retry.py", line 447, in increment
    raise reraise(type(error), error, _stacktrace)
          ^^^^^^^^^^^^^^^^^^^^^^^^^^^^^^^^^^^^^^^^
  File "/usr/lib/python3/dist-packages/urllib3/util/util.py", line 39, in reraise
    raise value
  File "/usr/lib/python3/dist-packages/urllib3/connectionpool.py", line 791, in urlopen
    response = self._make_request(
               ^^^^^^^^^^^^^^^^^^^
  File "/usr/lib/python3/dist-packages/urllib3/connectionpool.py", line 497, in _make_request
    conn.request(
  File "/usr/lib/python3/dist-packages/urllib3/connection.py", line 395, in request
    self.endheaders()
  File "/usr/lib/python3.12/http/client.py", line 1331, in endheaders
    self._send_output(message_body, encode_chunked=encode_chunked)
  File "/usr/lib/python3.12/http/client.py", line 1091, in _send_output
    self.send(msg)
  File "/usr/lib/python3.12/http/client.py", line 1035, in send
    self.connect()
  File "/usr/lib/python3/dist-packages/urllib3/connection.py", line 243, in connect
    self.sock = self._new_conn()
                ^^^^^^^^^^^^^^^^
  File "/usr/lib/python3/dist-packages/urllib3/connection.py", line 218, in _new_conn
    raise NewConnectionError(
urllib3.exceptions.NewConnectionError: <urllib3.connection.HTTPConnection object at 0x7f1b37a9ecf0>: Failed to establish a new connection: [Errno 111] Connection refused

The above exception was the direct cause of the following exception:

Traceback (most recent call last):
  File "/home/runner/.local/lib/python3.12/site-packages/elastic_transport/_transport.py", line 344, in perform_request
    resp = node.perform_request(
           ^^^^^^^^^^^^^^^^^^^^^
  File "/home/runner/.local/lib/python3.12/site-packages/elastic_transport/_node/_http_urllib3.py", line 202, in perform_request
    raise err from e
elastic_transport.ConnectionError: Connection error caused by: NewConnectionError(<urllib3.connection.HTTPConnection object at 0x7f1b37a9ecf0>: Failed to establish a new connection: [Errno 111] Connection refused)
2025-08-02 15:26:22,137 - elastic_transport.transport - INFO - HEAD http://localhost:9200/ [status:N/A duration:0.000s]
2025-08-02 15:26:22,137 - elastic_transport.node_pool - WARNING - Node <Urllib3HttpNode(http://localhost:9200)> has failed for 11 times in a row, putting on 30 second timeout
2025-08-02 15:26:22,137 - elastic_transport.transport - WARNING - Retrying request after failure (attempt 2 of 3)
Traceback (most recent call last):
  File "/usr/lib/python3/dist-packages/urllib3/connection.py", line 203, in _new_conn
    sock = connection.create_connection(
           ^^^^^^^^^^^^^^^^^^^^^^^^^^^^^
  File "/usr/lib/python3/dist-packages/urllib3/util/connection.py", line 85, in create_connection
    raise err
  File "/usr/lib/python3/dist-packages/urllib3/util/connection.py", line 73, in create_connection
    sock.connect(sa)
ConnectionRefusedError: [Errno 111] Connection refused

The above exception was the direct cause of the following exception:

Traceback (most recent call last):
  File "/home/runner/.local/lib/python3.12/site-packages/elastic_transport/_node/_http_urllib3.py", line 167, in perform_request
    response = self.pool.urlopen(
               ^^^^^^^^^^^^^^^^^^
  File "/usr/lib/python3/dist-packages/urllib3/connectionpool.py", line 845, in urlopen
    retries = retries.increment(
              ^^^^^^^^^^^^^^^^^^
  File "/usr/lib/python3/dist-packages/urllib3/util/retry.py", line 447, in increment
    raise reraise(type(error), error, _stacktrace)
          ^^^^^^^^^^^^^^^^^^^^^^^^^^^^^^^^^^^^^^^^
  File "/usr/lib/python3/dist-packages/urllib3/util/util.py", line 39, in reraise
    raise value
  File "/usr/lib/python3/dist-packages/urllib3/connectionpool.py", line 791, in urlopen
    response = self._make_request(
               ^^^^^^^^^^^^^^^^^^^
  File "/usr/lib/python3/dist-packages/urllib3/connectionpool.py", line 497, in _make_request
    conn.request(
  File "/usr/lib/python3/dist-packages/urllib3/connection.py", line 395, in request
    self.endheaders()
  File "/usr/lib/python3.12/http/client.py", line 1331, in endheaders
    self._send_output(message_body, encode_chunked=encode_chunked)
  File "/usr/lib/python3.12/http/client.py", line 1091, in _send_output
    self.send(msg)
  File "/usr/lib/python3.12/http/client.py", line 1035, in send
    self.connect()
  File "/usr/lib/python3/dist-packages/urllib3/connection.py", line 243, in connect
    self.sock = self._new_conn()
                ^^^^^^^^^^^^^^^^
  File "/usr/lib/python3/dist-packages/urllib3/connection.py", line 218, in _new_conn
    raise NewConnectionError(
urllib3.exceptions.NewConnectionError: <urllib3.connection.HTTPConnection object at 0x7f1b37c069f0>: Failed to establish a new connection: [Errno 111] Connection refused

The above exception was the direct cause of the following exception:

Traceback (most recent call last):
  File "/home/runner/.local/lib/python3.12/site-packages/elastic_transport/_transport.py", line 344, in perform_request
    resp = node.perform_request(
           ^^^^^^^^^^^^^^^^^^^^^
  File "/home/runner/.local/lib/python3.12/site-packages/elastic_transport/_node/_http_urllib3.py", line 202, in perform_request
    raise err from e
elastic_transport.ConnectionError: Connection error caused by: NewConnectionError(<urllib3.connection.HTTPConnection object at 0x7f1b37c069f0>: Failed to establish a new connection: [Errno 111] Connection refused)
2025-08-02 15:26:22,138 - elastic_transport.transport - INFO - HEAD http://localhost:9200/ [status:N/A duration:0.000s]
2025-08-02 15:26:22,138 - elastic_transport.node_pool - WARNING - Node <Urllib3HttpNode(http://localhost:9200)> has failed for 12 times in a row, putting on 30 second timeout
2025-08-02 15:26:22,138 - src.pipeline.pipeline_processor - INFO - Pipeline system stopped
2025-08-02 15:26:36,302 - src.pipeline.classifier - INFO - No saved model found, will need to train
2025-08-02 15:26:36,304 - elastic_transport.transport - INFO - HEAD http://localhost:9200/ [status:N/A duration:0.001s]
2025-08-02 15:26:36,304 - elastic_transport.node_pool - WARNING - Node <Urllib3HttpNode(http://localhost:9200)> has failed for 1 times in a row, putting on 1 second timeout
2025-08-02 15:26:36,304 - elastic_transport.transport - WARNING - Retrying request after failure (attempt 0 of 3)
Traceback (most recent call last):
  File "/usr/lib/python3/dist-packages/urllib3/connection.py", line 203, in _new_conn
    sock = connection.create_connection(
           ^^^^^^^^^^^^^^^^^^^^^^^^^^^^^
  File "/usr/lib/python3/dist-packages/urllib3/util/connection.py", line 85, in create_connection
    raise err
  File "/usr/lib/python3/dist-packages/urllib3/util/connection.py", line 73, in create_connection
    sock.connect(sa)
ConnectionRefusedError: [Errno 111] Connection refused

The above exception was the direct cause of the following exception:

Traceback (most recent call last):
  File "/home/runner/.local/lib/python3.12/site-packages/elastic_transport/_node/_http_urllib3.py", line 167, in perform_request
    response = self.pool.urlopen(
               ^^^^^^^^^^^^^^^^^^
  File "/usr/lib/python3/dist-packages/urllib3/connectionpool.py", line 845, in urlopen
    retries = retries.increment(
              ^^^^^^^^^^^^^^^^^^
  File "/usr/lib/python3/dist-packages/urllib3/util/retry.py", line 447, in increment
    raise reraise(type(error), error, _stacktrace)
          ^^^^^^^^^^^^^^^^^^^^^^^^^^^^^^^^^^^^^^^^
  File "/usr/lib/python3/dist-packages/urllib3/util/util.py", line 39, in reraise
    raise value
  File "/usr/lib/python3/dist-packages/urllib3/connectionpool.py", line 791, in urlopen
    response = self._make_request(
               ^^^^^^^^^^^^^^^^^^^
  File "/usr/lib/python3/dist-packages/urllib3/connectionpool.py", line 497, in _make_request
    conn.request(
  File "/usr/lib/python3/dist-packages/urllib3/connection.py", line 395, in request
    self.endheaders()
  File "/usr/lib/python3.12/http/client.py", line 1331, in endheaders
    self._send_output(message_body, encode_chunked=encode_chunked)
  File "/usr/lib/python3.12/http/client.py", line 1091, in _send_output
    self.send(msg)
  File "/usr/lib/python3.12/http/client.py", line 1035, in send
    self.connect()
  File "/usr/lib/python3/dist-packages/urllib3/connection.py", line 243, in connect
    self.sock = self._new_conn()
                ^^^^^^^^^^^^^^^^
  File "/usr/lib/python3/dist-packages/urllib3/connection.py", line 218, in _new_conn
    raise NewConnectionError(
urllib3.exceptions.NewConnectionError: <urllib3.connection.HTTPConnection object at 0x7f3378ceef30>: Failed to establish a new connection: [Errno 111] Connection refused

The above exception was the direct cause of the following exception:

Traceback (most recent call last):
  File "/home/runner/.local/lib/python3.12/site-packages/elastic_transport/_transport.py", line 344, in perform_request
    resp = node.perform_request(
           ^^^^^^^^^^^^^^^^^^^^^
  File "/home/runner/.local/lib/python3.12/site-packages/elastic_transport/_node/_http_urllib3.py", line 202, in perform_request
    raise err from e
elastic_transport.ConnectionError: Connection error caused by: NewConnectionError(<urllib3.connection.HTTPConnection object at 0x7f3378ceef30>: Failed to establish a new connection: [Errno 111] Connection refused)
2025-08-02 15:26:36,306 - elastic_transport.transport - INFO - HEAD http://localhost:9200/ [status:N/A duration:0.000s]
2025-08-02 15:26:36,306 - elastic_transport.node_pool - WARNING - Node <Urllib3HttpNode(http://localhost:9200)> has failed for 2 times in a row, putting on 2 second timeout
2025-08-02 15:26:36,307 - elastic_transport.transport - WARNING - Retrying request after failure (attempt 1 of 3)
Traceback (most recent call last):
  File "/usr/lib/python3/dist-packages/urllib3/connection.py", line 203, in _new_conn
    sock = connection.create_connection(
           ^^^^^^^^^^^^^^^^^^^^^^^^^^^^^
  File "/usr/lib/python3/dist-packages/urllib3/util/connection.py", line 85, in create_connection
    raise err
  File "/usr/lib/python3/dist-packages/urllib3/util/connection.py", line 73, in create_connection
    sock.connect(sa)
ConnectionRefusedError: [Errno 111] Connection refused

The above exception was the direct cause of the following exception:

Traceback (most recent call last):
  File "/home/runner/.local/lib/python3.12/site-packages/elastic_transport/_node/_http_urllib3.py", line 167, in perform_request
    response = self.pool.urlopen(
               ^^^^^^^^^^^^^^^^^^
  File "/usr/lib/python3/dist-packages/urllib3/connectionpool.py", line 845, in urlopen
    retries = retries.increment(
              ^^^^^^^^^^^^^^^^^^
  File "/usr/lib/python3/dist-packages/urllib3/util/retry.py", line 447, in increment
    raise reraise(type(error), error, _stacktrace)
          ^^^^^^^^^^^^^^^^^^^^^^^^^^^^^^^^^^^^^^^^
  File "/usr/lib/python3/dist-packages/urllib3/util/util.py", line 39, in reraise
    raise value
  File "/usr/lib/python3/dist-packages/urllib3/connectionpool.py", line 791, in urlopen
    response = self._make_request(
               ^^^^^^^^^^^^^^^^^^^
  File "/usr/lib/python3/dist-packages/urllib3/connectionpool.py", line 497, in _make_request
    conn.request(
  File "/usr/lib/python3/dist-packages/urllib3/connection.py", line 395, in request
    self.endheaders()
  File "/usr/lib/python3.12/http/client.py", line 1331, in endheaders
    self._send_output(message_body, encode_chunked=encode_chunked)
  File "/usr/lib/python3.12/http/client.py", line 1091, in _send_output
    self.send(msg)
  File "/usr/lib/python3.12/http/client.py", line 1035, in send
    self.connect()
  File "/usr/lib/python3/dist-packages/urllib3/connection.py", line 243, in connect
    self.sock = self._new_conn()
                ^^^^^^^^^^^^^^^^
  File "/usr/lib/python3/dist-packages/urllib3/connection.py", line 218, in _new_conn
    raise NewConnectionError(
urllib3.exceptions.NewConnectionError: <urllib3.connection.HTTPConnection object at 0x7f3378c6ff80>: Failed to establish a new connection: [Errno 111] Connection refused

The above exception was the direct cause of the following exception:

Traceback (most recent call last):
  File "/home/runner/.local/lib/python3.12/site-packages/elastic_transport/_transport.py", line 344, in perform_request
    resp = node.perform_request(
           ^^^^^^^^^^^^^^^^^^^^^
  File "/home/runner/.local/lib/python3.12/site-packages/elastic_transport/_node/_http_urllib3.py", line 202, in perform_request
    raise err from e
elastic_transport.ConnectionError: Connection error caused by: NewConnectionError(<urllib3.connection.HTTPConnection object at 0x7f3378c6ff80>: Failed to establish a new connection: [Errno 111] Connection refused)
2025-08-02 15:26:36,308 - elastic_transport.transport - INFO - HEAD http://localhost:9200/ [status:N/A duration:0.000s]
2025-08-02 15:26:36,308 - elastic_transport.node_pool - WARNING - Node <Urllib3HttpNode(http://localhost:9200)> has failed for 3 times in a row, putting on 4 second timeout
2025-08-02 15:26:36,308 - elastic_transport.transport - WARNING - Retrying request after failure (attempt 2 of 3)
Traceback (most recent call last):
  File "/usr/lib/python3/dist-packages/urllib3/connection.py", line 203, in _new_conn
    sock = connection.create_connection(
           ^^^^^^^^^^^^^^^^^^^^^^^^^^^^^
  File "/usr/lib/python3/dist-packages/urllib3/util/connection.py", line 85, in create_connection
    raise err
  File "/usr/lib/python3/dist-packages/urllib3/util/connection.py", line 73, in create_connection
    sock.connect(sa)
ConnectionRefusedError: [Errno 111] Connection refused

The above exception was the direct cause of the following exception:

Traceback (most recent call last):
  File "/home/runner/.local/lib/python3.12/site-packages/elastic_transport/_node/_http_urllib3.py", line 167, in perform_request
    response = self.pool.urlopen(
               ^^^^^^^^^^^^^^^^^^
  File "/usr/lib/python3/dist-packages/urllib3/connectionpool.py", line 845, in urlopen
    retries = retries.increment(
              ^^^^^^^^^^^^^^^^^^
  File "/usr/lib/python3/dist-packages/urllib3/util/retry.py", line 447, in increment
    raise reraise(type(error), error, _stacktrace)
          ^^^^^^^^^^^^^^^^^^^^^^^^^^^^^^^^^^^^^^^^
  File "/usr/lib/python3/dist-packages/urllib3/util/util.py", line 39, in reraise
    raise value
  File "/usr/lib/python3/dist-packages/urllib3/connectionpool.py", line 791, in urlopen
    response = self._make_request(
               ^^^^^^^^^^^^^^^^^^^
  File "/usr/lib/python3/dist-packages/urllib3/connectionpool.py", line 497, in _make_request
    conn.request(
  File "/usr/lib/python3/dist-packages/urllib3/connection.py", line 395, in request
    self.endheaders()
  File "/usr/lib/python3.12/http/client.py", line 1331, in endheaders
    self._send_output(message_body, encode_chunked=encode_chunked)
  File "/usr/lib/python3.12/http/client.py", line 1091, in _send_output
    self.send(msg)
  File "/usr/lib/python3.12/http/client.py", line 1035, in send
    self.connect()
  File "/usr/lib/python3/dist-packages/urllib3/connection.py", line 243, in connect
    self.sock = self._new_conn()
                ^^^^^^^^^^^^^^^^
  File "/usr/lib/python3/dist-packages/urllib3/connection.py", line 218, in _new_conn
    raise NewConnectionError(
urllib3.exceptions.NewConnectionError: <urllib3.connection.HTTPConnection object at 0x7f337938fef0>: Failed to establish a new connection: [Errno 111] Connection refused

The above exception was the direct cause of the following exception:

Traceback (most recent call last):
  File "/home/runner/.local/lib/python3.12/site-packages/elastic_transport/_transport.py", line 344, in perform_request
    resp = node.perform_request(
           ^^^^^^^^^^^^^^^^^^^^^
  File "/home/runner/.local/lib/python3.12/site-packages/elastic_transport/_node/_http_urllib3.py", line 202, in perform_request
    raise err from e
elastic_transport.ConnectionError: Connection error caused by: NewConnectionError(<urllib3.connection.HTTPConnection object at 0x7f337938fef0>: Failed to establish a new connection: [Errno 111] Connection refused)
2025-08-02 15:26:36,310 - elastic_transport.transport - INFO - HEAD http://localhost:9200/ [status:N/A duration:0.000s]
2025-08-02 15:26:36,310 - elastic_transport.node_pool - WARNING - Node <Urllib3HttpNode(http://localhost:9200)> has failed for 4 times in a row, putting on 8 second timeout
2025-08-02 15:26:36,310 - src.pipeline.elasticsearch_indexer - ERROR - Cannot connect to Elasticsearch at http://localhost:9200
2025-08-02 15:26:36,310 - src.pipeline.pipeline_processor - INFO - Pipeline processor initialized
2025-08-02 15:26:36,310 - src.pipeline.pipeline_processor - INFO - Pipeline manager initialized
2025-08-02 15:26:36,310 - src.pipeline.pipeline_processor - INFO - Starting PDF processing pipeline...
2025-08-02 15:26:36,311 - src.pipeline.ocr_processor - ERROR - Tesseract installation test failed: tesseract is not installed or it's not in your PATH. See README file for more information.
2025-08-02 15:26:36,311 - elastic_transport.transport - INFO - HEAD http://localhost:9200/ [status:N/A duration:0.000s]
2025-08-02 15:26:36,311 - elastic_transport.node_pool - WARNING - Node <Urllib3HttpNode(http://localhost:9200)> has failed for 5 times in a row, putting on 16 second timeout
2025-08-02 15:26:36,311 - elastic_transport.transport - WARNING - Retrying request after failure (attempt 0 of 3)
Traceback (most recent call last):
  File "/usr/lib/python3/dist-packages/urllib3/connection.py", line 203, in _new_conn
    sock = connection.create_connection(
           ^^^^^^^^^^^^^^^^^^^^^^^^^^^^^
  File "/usr/lib/python3/dist-packages/urllib3/util/connection.py", line 85, in create_connection
    raise err
  File "/usr/lib/python3/dist-packages/urllib3/util/connection.py", line 73, in create_connection
    sock.connect(sa)
ConnectionRefusedError: [Errno 111] Connection refused

The above exception was the direct cause of the following exception:

Traceback (most recent call last):
  File "/home/runner/.local/lib/python3.12/site-packages/elastic_transport/_node/_http_urllib3.py", line 167, in perform_request
    response = self.pool.urlopen(
               ^^^^^^^^^^^^^^^^^^
  File "/usr/lib/python3/dist-packages/urllib3/connectionpool.py", line 845, in urlopen
    retries = retries.increment(
              ^^^^^^^^^^^^^^^^^^
  File "/usr/lib/python3/dist-packages/urllib3/util/retry.py", line 447, in increment
    raise reraise(type(error), error, _stacktrace)
          ^^^^^^^^^^^^^^^^^^^^^^^^^^^^^^^^^^^^^^^^
  File "/usr/lib/python3/dist-packages/urllib3/util/util.py", line 39, in reraise
    raise value
  File "/usr/lib/python3/dist-packages/urllib3/connectionpool.py", line 791, in urlopen
    response = self._make_request(
               ^^^^^^^^^^^^^^^^^^^
  File "/usr/lib/python3/dist-packages/urllib3/connectionpool.py", line 497, in _make_request
    conn.request(
  File "/usr/lib/python3/dist-packages/urllib3/connection.py", line 395, in request
    self.endheaders()
  File "/usr/lib/python3.12/http/client.py", line 1331, in endheaders
    self._send_output(message_body, encode_chunked=encode_chunked)
  File "/usr/lib/python3.12/http/client.py", line 1091, in _send_output
    self.send(msg)
  File "/usr/lib/python3.12/http/client.py", line 1035, in send
    self.connect()
  File "/usr/lib/python3/dist-packages/urllib3/connection.py", line 243, in connect
    self.sock = self._new_conn()
                ^^^^^^^^^^^^^^^^
  File "/usr/lib/python3/dist-packages/urllib3/connection.py", line 218, in _new_conn
    raise NewConnectionError(
urllib3.exceptions.NewConnectionError: <urllib3.connection.HTTPConnection object at 0x7f3378c8e540>: Failed to establish a new connection: [Errno 111] Connection refused

The above exception was the direct cause of the following exception:

Traceback (most recent call last):
  File "/home/runner/.local/lib/python3.12/site-packages/elastic_transport/_transport.py", line 344, in perform_request
    resp = node.perform_request(
           ^^^^^^^^^^^^^^^^^^^^^
  File "/home/runner/.local/lib/python3.12/site-packages/elastic_transport/_node/_http_urllib3.py", line 202, in perform_request
    raise err from e
elastic_transport.ConnectionError: Connection error caused by: NewConnectionError(<urllib3.connection.HTTPConnection object at 0x7f3378c8e540>: Failed to establish a new connection: [Errno 111] Connection refused)
2025-08-02 15:26:36,313 - elastic_transport.transport - INFO - HEAD http://localhost:9200/ [status:N/A duration:0.000s]
2025-08-02 15:26:36,313 - elastic_transport.node_pool - WARNING - Node <Urllib3HttpNode(http://localhost:9200)> has failed for 6 times in a row, putting on 30 second timeout
2025-08-02 15:26:36,313 - elastic_transport.transport - WARNING - Retrying request after failure (attempt 1 of 3)
Traceback (most recent call last):
  File "/usr/lib/python3/dist-packages/urllib3/connection.py", line 203, in _new_conn
    sock = connection.create_connection(
           ^^^^^^^^^^^^^^^^^^^^^^^^^^^^^
  File "/usr/lib/python3/dist-packages/urllib3/util/connection.py", line 85, in create_connection
    raise err
  File "/usr/lib/python3/dist-packages/urllib3/util/connection.py", line 73, in create_connection
    sock.connect(sa)
ConnectionRefusedError: [Errno 111] Connection refused

The above exception was the direct cause of the following exception:

Traceback (most recent call last):
  File "/home/runner/.local/lib/python3.12/site-packages/elastic_transport/_node/_http_urllib3.py", line 167, in perform_request
    response = self.pool.urlopen(
               ^^^^^^^^^^^^^^^^^^
  File "/usr/lib/python3/dist-packages/urllib3/connectionpool.py", line 845, in urlopen
    retries = retries.increment(
              ^^^^^^^^^^^^^^^^^^
  File "/usr/lib/python3/dist-packages/urllib3/util/retry.py", line 447, in increment
    raise reraise(type(error), error, _stacktrace)
          ^^^^^^^^^^^^^^^^^^^^^^^^^^^^^^^^^^^^^^^^
  File "/usr/lib/python3/dist-packages/urllib3/util/util.py", line 39, in reraise
    raise value
  File "/usr/lib/python3/dist-packages/urllib3/connectionpool.py", line 791, in urlopen
    response = self._make_request(
               ^^^^^^^^^^^^^^^^^^^
  File "/usr/lib/python3/dist-packages/urllib3/connectionpool.py", line 497, in _make_request
    conn.request(
  File "/usr/lib/python3/dist-packages/urllib3/connection.py", line 395, in request
    self.endheaders()
  File "/usr/lib/python3.12/http/client.py", line 1331, in endheaders
    self._send_output(message_body, encode_chunked=encode_chunked)
  File "/usr/lib/python3.12/http/client.py", line 1091, in _send_output
    self.send(msg)
  File "/usr/lib/python3.12/http/client.py", line 1035, in send
    self.connect()
  File "/usr/lib/python3/dist-packages/urllib3/connection.py", line 243, in connect
    self.sock = self._new_conn()
                ^^^^^^^^^^^^^^^^
  File "/usr/lib/python3/dist-packages/urllib3/connection.py", line 218, in _new_conn
    raise NewConnectionError(
urllib3.exceptions.NewConnectionError: <urllib3.connection.HTTPConnection object at 0x7f3378c8e5d0>: Failed to establish a new connection: [Errno 111] Connection refused

The above exception was the direct cause of the following exception:

Traceback (most recent call last):
  File "/home/runner/.local/lib/python3.12/site-packages/elastic_transport/_transport.py", line 344, in perform_request
    resp = node.perform_request(
           ^^^^^^^^^^^^^^^^^^^^^
  File "/home/runner/.local/lib/python3.12/site-packages/elastic_transport/_node/_http_urllib3.py", line 202, in perform_request
    raise err from e
elastic_transport.ConnectionError: Connection error caused by: NewConnectionError(<urllib3.connection.HTTPConnection object at 0x7f3378c8e5d0>: Failed to establish a new connection: [Errno 111] Connection refused)
2025-08-02 15:26:36,314 - elastic_transport.transport - INFO - HEAD http://localhost:9200/ [status:N/A duration:0.000s]
2025-08-02 15:26:36,314 - elastic_transport.node_pool - WARNING - Node <Urllib3HttpNode(http://localhost:9200)> has failed for 7 times in a row, putting on 30 second timeout
2025-08-02 15:26:36,314 - elastic_transport.transport - WARNING - Retrying request after failure (attempt 2 of 3)
Traceback (most recent call last):
  File "/usr/lib/python3/dist-packages/urllib3/connection.py", line 203, in _new_conn
    sock = connection.create_connection(
           ^^^^^^^^^^^^^^^^^^^^^^^^^^^^^
  File "/usr/lib/python3/dist-packages/urllib3/util/connection.py", line 85, in create_connection
    raise err
  File "/usr/lib/python3/dist-packages/urllib3/util/connection.py", line 73, in create_connection
    sock.connect(sa)
ConnectionRefusedError: [Errno 111] Connection refused

The above exception was the direct cause of the following exception:

Traceback (most recent call last):
  File "/home/runner/.local/lib/python3.12/site-packages/elastic_transport/_node/_http_urllib3.py", line 167, in perform_request
    response = self.pool.urlopen(
               ^^^^^^^^^^^^^^^^^^
  File "/usr/lib/python3/dist-packages/urllib3/connectionpool.py", line 845, in urlopen
    retries = retries.increment(
              ^^^^^^^^^^^^^^^^^^
  File "/usr/lib/python3/dist-packages/urllib3/util/retry.py", line 447, in increment
    raise reraise(type(error), error, _stacktrace)
          ^^^^^^^^^^^^^^^^^^^^^^^^^^^^^^^^^^^^^^^^
  File "/usr/lib/python3/dist-packages/urllib3/util/util.py", line 39, in reraise
    raise value
  File "/usr/lib/python3/dist-packages/urllib3/connectionpool.py", line 791, in urlopen
    response = self._make_request(
               ^^^^^^^^^^^^^^^^^^^
  File "/usr/lib/python3/dist-packages/urllib3/connectionpool.py", line 497, in _make_request
    conn.request(
  File "/usr/lib/python3/dist-packages/urllib3/connection.py", line 395, in request
    self.endheaders()
  File "/usr/lib/python3.12/http/client.py", line 1331, in endheaders
    self._send_output(message_body, encode_chunked=encode_chunked)
  File "/usr/lib/python3.12/http/client.py", line 1091, in _send_output
    self.send(msg)
  File "/usr/lib/python3.12/http/client.py", line 1035, in send
    self.connect()
  File "/usr/lib/python3/dist-packages/urllib3/connection.py", line 243, in connect
    self.sock = self._new_conn()
                ^^^^^^^^^^^^^^^^
  File "/usr/lib/python3/dist-packages/urllib3/connection.py", line 218, in _new_conn
    raise NewConnectionError(
urllib3.exceptions.NewConnectionError: <urllib3.connection.HTTPConnection object at 0x7f3378c8eab0>: Failed to establish a new connection: [Errno 111] Connection refused

The above exception was the direct cause of the following exception:

Traceback (most recent call last):
  File "/home/runner/.local/lib/python3.12/site-packages/elastic_transport/_transport.py", line 344, in perform_request
    resp = node.perform_request(
           ^^^^^^^^^^^^^^^^^^^^^
  File "/home/runner/.local/lib/python3.12/site-packages/elastic_transport/_node/_http_urllib3.py", line 202, in perform_request
    raise err from e
elastic_transport.ConnectionError: Connection error caused by: NewConnectionError(<urllib3.connection.HTTPConnection object at 0x7f3378c8eab0>: Failed to establish a new connection: [Errno 111] Connection refused)
2025-08-02 15:26:36,316 - elastic_transport.transport - INFO - HEAD http://localhost:9200/ [status:N/A duration:0.000s]
2025-08-02 15:26:36,316 - elastic_transport.node_pool - WARNING - Node <Urllib3HttpNode(http://localhost:9200)> has failed for 8 times in a row, putting on 30 second timeout
2025-08-02 15:26:36,316 - src.pipeline.pipeline_processor - INFO - ✓ format_detector: OK
2025-08-02 15:26:36,316 - src.pipeline.pipeline_processor - WARNING - ✗ ocr_processor: tesseract is not installed or it's not in your PATH. See README file for more information.
2025-08-02 15:26:36,316 - src.pipeline.pipeline_processor - INFO - ✓ text_extractor: OK
2025-08-02 15:26:36,316 - src.pipeline.pipeline_processor - INFO - ✓ classifier: OK
2025-08-02 15:26:36,316 - src.pipeline.pipeline_processor - WARNING - ✗ elasticsearch: Cannot reach Elasticsearch
2025-08-02 15:26:36,316 - src.pipeline.pipeline_processor - INFO - Setting up default classifier with sample data...
2025-08-02 15:26:36,318 - src.pipeline.classifier - ERROR - Error training model: The test_size = 6 should be greater or equal to the number of classes = 10
2025-08-02 15:26:36,319 - src.pipeline.pipeline_processor - ERROR - Failed to train default classifier: The test_size = 6 should be greater or equal to the number of classes = 10
2025-08-02 15:26:36,319 - src.pipeline.pipeline_processor - INFO - Pipeline system started successfully
2025-08-02 15:26:36,332 - src.pipeline.classifier - INFO - No saved model found, will need to train
2025-08-02 15:26:36,333 - elastic_transport.transport - INFO - HEAD http://localhost:9200/ [status:N/A duration:0.001s]
2025-08-02 15:26:36,334 - elastic_transport.node_pool - WARNING - Node <Urllib3HttpNode(http://localhost:9200)> has failed for 1 times in a row, putting on 1 second timeout
2025-08-02 15:26:36,334 - elastic_transport.transport - WARNING - Retrying request after failure (attempt 0 of 3)
Traceback (most recent call last):
  File "/usr/lib/python3/dist-packages/urllib3/connection.py", line 203, in _new_conn
    sock = connection.create_connection(
           ^^^^^^^^^^^^^^^^^^^^^^^^^^^^^
  File "/usr/lib/python3/dist-packages/urllib3/util/connection.py", line 85, in create_connection
    raise err
  File "/usr/lib/python3/dist-packages/urllib3/util/connection.py", line 73, in create_connection
    sock.connect(sa)
ConnectionRefusedError: [Errno 111] Connection refused

The above exception was the direct cause of the following exception:

Traceback (most recent call last):
  File "/home/runner/.local/lib/python3.12/site-packages/elastic_transport/_node/_http_urllib3.py", line 167, in perform_request
    response = self.pool.urlopen(
               ^^^^^^^^^^^^^^^^^^
  File "/usr/lib/python3/dist-packages/urllib3/connectionpool.py", line 845, in urlopen
    retries = retries.increment(
              ^^^^^^^^^^^^^^^^^^
  File "/usr/lib/python3/dist-packages/urllib3/util/retry.py", line 447, in increment
    raise reraise(type(error), error, _stacktrace)
          ^^^^^^^^^^^^^^^^^^^^^^^^^^^^^^^^^^^^^^^^
  File "/usr/lib/python3/dist-packages/urllib3/util/util.py", line 39, in reraise
    raise value
  File "/usr/lib/python3/dist-packages/urllib3/connectionpool.py", line 791, in urlopen
    response = self._make_request(
               ^^^^^^^^^^^^^^^^^^^
  File "/usr/lib/python3/dist-packages/urllib3/connectionpool.py", line 497, in _make_request
    conn.request(
  File "/usr/lib/python3/dist-packages/urllib3/connection.py", line 395, in request
    self.endheaders()
  File "/usr/lib/python3.12/http/client.py", line 1331, in endheaders
    self._send_output(message_body, encode_chunked=encode_chunked)
  File "/usr/lib/python3.12/http/client.py", line 1091, in _send_output
    self.send(msg)
  File "/usr/lib/python3.12/http/client.py", line 1035, in send
    self.connect()
  File "/usr/lib/python3/dist-packages/urllib3/connection.py", line 243, in connect
    self.sock = self._new_conn()
                ^^^^^^^^^^^^^^^^
  File "/usr/lib/python3/dist-packages/urllib3/connection.py", line 218, in _new_conn
    raise NewConnectionError(
urllib3.exceptions.NewConnectionError: <urllib3.connection.HTTPConnection object at 0x7f3378ba4b00>: Failed to establish a new connection: [Errno 111] Connection refused

The above exception was the direct cause of the following exception:

Traceback (most recent call last):
  File "/home/runner/.local/lib/python3.12/site-packages/elastic_transport/_transport.py", line 344, in perform_request
    resp = node.perform_request(
           ^^^^^^^^^^^^^^^^^^^^^
  File "/home/runner/.local/lib/python3.12/site-packages/elastic_transport/_node/_http_urllib3.py", line 202, in perform_request
    raise err from e
elastic_transport.ConnectionError: Connection error caused by: NewConnectionError(<urllib3.connection.HTTPConnection object at 0x7f3378ba4b00>: Failed to establish a new connection: [Errno 111] Connection refused)
2025-08-02 15:26:36,335 - elastic_transport.transport - INFO - HEAD http://localhost:9200/ [status:N/A duration:0.000s]
2025-08-02 15:26:36,335 - elastic_transport.node_pool - WARNING - Node <Urllib3HttpNode(http://localhost:9200)> has failed for 2 times in a row, putting on 2 second timeout
2025-08-02 15:26:36,335 - elastic_transport.transport - WARNING - Retrying request after failure (attempt 1 of 3)
Traceback (most recent call last):
  File "/usr/lib/python3/dist-packages/urllib3/connection.py", line 203, in _new_conn
    sock = connection.create_connection(
           ^^^^^^^^^^^^^^^^^^^^^^^^^^^^^
  File "/usr/lib/python3/dist-packages/urllib3/util/connection.py", line 85, in create_connection
    raise err
  File "/usr/lib/python3/dist-packages/urllib3/util/connection.py", line 73, in create_connection
    sock.connect(sa)
ConnectionRefusedError: [Errno 111] Connection refused

The above exception was the direct cause of the following exception:

Traceback (most recent call last):
  File "/home/runner/.local/lib/python3.12/site-packages/elastic_transport/_node/_http_urllib3.py", line 167, in perform_request
    response = self.pool.urlopen(
               ^^^^^^^^^^^^^^^^^^
  File "/usr/lib/python3/dist-packages/urllib3/connectionpool.py", line 845, in urlopen
    retries = retries.increment(
              ^^^^^^^^^^^^^^^^^^
  File "/usr/lib/python3/dist-packages/urllib3/util/retry.py", line 447, in increment
    raise reraise(type(error), error, _stacktrace)
          ^^^^^^^^^^^^^^^^^^^^^^^^^^^^^^^^^^^^^^^^
  File "/usr/lib/python3/dist-packages/urllib3/util/util.py", line 39, in reraise
    raise value
  File "/usr/lib/python3/dist-packages/urllib3/connectionpool.py", line 791, in urlopen
    response = self._make_request(
               ^^^^^^^^^^^^^^^^^^^
  File "/usr/lib/python3/dist-packages/urllib3/connectionpool.py", line 497, in _make_request
    conn.request(
  File "/usr/lib/python3/dist-packages/urllib3/connection.py", line 395, in request
    self.endheaders()
  File "/usr/lib/python3.12/http/client.py", line 1331, in endheaders
    self._send_output(message_body, encode_chunked=encode_chunked)
  File "/usr/lib/python3.12/http/client.py", line 1091, in _send_output
    self.send(msg)
  File "/usr/lib/python3.12/http/client.py", line 1035, in send
    self.connect()
  File "/usr/lib/python3/dist-packages/urllib3/connection.py", line 243, in connect
    self.sock = self._new_conn()
                ^^^^^^^^^^^^^^^^
  File "/usr/lib/python3/dist-packages/urllib3/connection.py", line 218, in _new_conn
    raise NewConnectionError(
urllib3.exceptions.NewConnectionError: <urllib3.connection.HTTPConnection object at 0x7f3378ba4d10>: Failed to establish a new connection: [Errno 111] Connection refused

The above exception was the direct cause of the following exception:

Traceback (most recent call last):
  File "/home/runner/.local/lib/python3.12/site-packages/elastic_transport/_transport.py", line 344, in perform_request
    resp = node.perform_request(
           ^^^^^^^^^^^^^^^^^^^^^
  File "/home/runner/.local/lib/python3.12/site-packages/elastic_transport/_node/_http_urllib3.py", line 202, in perform_request
    raise err from e
elastic_transport.ConnectionError: Connection error caused by: NewConnectionError(<urllib3.connection.HTTPConnection object at 0x7f3378ba4d10>: Failed to establish a new connection: [Errno 111] Connection refused)
2025-08-02 15:26:36,337 - elastic_transport.transport - INFO - HEAD http://localhost:9200/ [status:N/A duration:0.000s]
2025-08-02 15:26:36,337 - elastic_transport.node_pool - WARNING - Node <Urllib3HttpNode(http://localhost:9200)> has failed for 3 times in a row, putting on 4 second timeout
2025-08-02 15:26:36,337 - elastic_transport.transport - WARNING - Retrying request after failure (attempt 2 of 3)
Traceback (most recent call last):
  File "/usr/lib/python3/dist-packages/urllib3/connection.py", line 203, in _new_conn
    sock = connection.create_connection(
           ^^^^^^^^^^^^^^^^^^^^^^^^^^^^^
  File "/usr/lib/python3/dist-packages/urllib3/util/connection.py", line 85, in create_connection
    raise err
  File "/usr/lib/python3/dist-packages/urllib3/util/connection.py", line 73, in create_connection
    sock.connect(sa)
ConnectionRefusedError: [Errno 111] Connection refused

The above exception was the direct cause of the following exception:

Traceback (most recent call last):
  File "/home/runner/.local/lib/python3.12/site-packages/elastic_transport/_node/_http_urllib3.py", line 167, in perform_request
    response = self.pool.urlopen(
               ^^^^^^^^^^^^^^^^^^
  File "/usr/lib/python3/dist-packages/urllib3/connectionpool.py", line 845, in urlopen
    retries = retries.increment(
              ^^^^^^^^^^^^^^^^^^
  File "/usr/lib/python3/dist-packages/urllib3/util/retry.py", line 447, in increment
    raise reraise(type(error), error, _stacktrace)
          ^^^^^^^^^^^^^^^^^^^^^^^^^^^^^^^^^^^^^^^^
  File "/usr/lib/python3/dist-packages/urllib3/util/util.py", line 39, in reraise
    raise value
  File "/usr/lib/python3/dist-packages/urllib3/connectionpool.py", line 791, in urlopen
    response = self._make_request(
               ^^^^^^^^^^^^^^^^^^^
  File "/usr/lib/python3/dist-packages/urllib3/connectionpool.py", line 497, in _make_request
    conn.request(
  File "/usr/lib/python3/dist-packages/urllib3/connection.py", line 395, in request
    self.endheaders()
  File "/usr/lib/python3.12/http/client.py", line 1331, in endheaders
    self._send_output(message_body, encode_chunked=encode_chunked)
  File "/usr/lib/python3.12/http/client.py", line 1091, in _send_output
    self.send(msg)
  File "/usr/lib/python3.12/http/client.py", line 1035, in send
    self.connect()
  File "/usr/lib/python3/dist-packages/urllib3/connection.py", line 243, in connect
    self.sock = self._new_conn()
                ^^^^^^^^^^^^^^^^
  File "/usr/lib/python3/dist-packages/urllib3/connection.py", line 218, in _new_conn
    raise NewConnectionError(
urllib3.exceptions.NewConnectionError: <urllib3.connection.HTTPConnection object at 0x7f3378ba4ef0>: Failed to establish a new connection: [Errno 111] Connection refused

The above exception was the direct cause of the following exception:

Traceback (most recent call last):
  File "/home/runner/.local/lib/python3.12/site-packages/elastic_transport/_transport.py", line 344, in perform_request
    resp = node.perform_request(
           ^^^^^^^^^^^^^^^^^^^^^
  File "/home/runner/.local/lib/python3.12/site-packages/elastic_transport/_node/_http_urllib3.py", line 202, in perform_request
    raise err from e
elastic_transport.ConnectionError: Connection error caused by: NewConnectionError(<urllib3.connection.HTTPConnection object at 0x7f3378ba4ef0>: Failed to establish a new connection: [Errno 111] Connection refused)
2025-08-02 15:26:36,338 - elastic_transport.transport - INFO - HEAD http://localhost:9200/ [status:N/A duration:0.000s]
2025-08-02 15:26:36,338 - elastic_transport.node_pool - WARNING - Node <Urllib3HttpNode(http://localhost:9200)> has failed for 4 times in a row, putting on 8 second timeout
2025-08-02 15:26:36,338 - src.pipeline.elasticsearch_indexer - ERROR - Cannot connect to Elasticsearch at http://localhost:9200
2025-08-02 15:26:36,338 - src.pipeline.pipeline_processor - INFO - Pipeline processor initialized
2025-08-02 15:26:36,338 - src.pipeline.pipeline_processor - INFO - Pipeline manager initialized
2025-08-02 15:26:36,338 - src.pipeline.pipeline_processor - INFO - Starting PDF processing pipeline...
2025-08-02 15:26:36,339 - src.pipeline.ocr_processor - ERROR - Tesseract installation test failed: tesseract is not installed or it's not in your PATH. See README file for more information.
2025-08-02 15:26:36,340 - elastic_transport.transport - INFO - HEAD http://localhost:9200/ [status:N/A duration:0.000s]
2025-08-02 15:26:36,340 - elastic_transport.node_pool - WARNING - Node <Urllib3HttpNode(http://localhost:9200)> has failed for 5 times in a row, putting on 16 second timeout
2025-08-02 15:26:36,340 - elastic_transport.transport - WARNING - Retrying request after failure (attempt 0 of 3)
Traceback (most recent call last):
  File "/usr/lib/python3/dist-packages/urllib3/connection.py", line 203, in _new_conn
    sock = connection.create_connection(
           ^^^^^^^^^^^^^^^^^^^^^^^^^^^^^
  File "/usr/lib/python3/dist-packages/urllib3/util/connection.py", line 85, in create_connection
    raise err
  File "/usr/lib/python3/dist-packages/urllib3/util/connection.py", line 73, in create_connection
    sock.connect(sa)
ConnectionRefusedError: [Errno 111] Connection refused

The above exception was the direct cause of the following exception:

Traceback (most recent call last):
  File "/home/runner/.local/lib/python3.12/site-packages/elastic_transport/_node/_http_urllib3.py", line 167, in perform_request
    response = self.pool.urlopen(
               ^^^^^^^^^^^^^^^^^^
  File "/usr/lib/python3/dist-packages/urllib3/connectionpool.py", line 845, in urlopen
    retries = retries.increment(
              ^^^^^^^^^^^^^^^^^^
  File "/usr/lib/python3/dist-packages/urllib3/util/retry.py", line 447, in increment
    raise reraise(type(error), error, _stacktrace)
          ^^^^^^^^^^^^^^^^^^^^^^^^^^^^^^^^^^^^^^^^
  File "/usr/lib/python3/dist-packages/urllib3/util/util.py", line 39, in reraise
    raise value
  File "/usr/lib/python3/dist-packages/urllib3/connectionpool.py", line 791, in urlopen
    response = self._make_request(
               ^^^^^^^^^^^^^^^^^^^
  File "/usr/lib/python3/dist-packages/urllib3/connectionpool.py", line 497, in _make_request
    conn.request(
  File "/usr/lib/python3/dist-packages/urllib3/connection.py", line 395, in request
    self.endheaders()
  File "/usr/lib/python3.12/http/client.py", line 1331, in endheaders
    self._send_output(message_body, encode_chunked=encode_chunked)
  File "/usr/lib/python3.12/http/client.py", line 1091, in _send_output
    self.send(msg)
  File "/usr/lib/python3.12/http/client.py", line 1035, in send
    self.connect()
  File "/usr/lib/python3/dist-packages/urllib3/connection.py", line 243, in connect
    self.sock = self._new_conn()
                ^^^^^^^^^^^^^^^^
  File "/usr/lib/python3/dist-packages/urllib3/connection.py", line 218, in _new_conn
    raise NewConnectionError(
urllib3.exceptions.NewConnectionError: <urllib3.connection.HTTPConnection object at 0x7f3378ba5100>: Failed to establish a new connection: [Errno 111] Connection refused

The above exception was the direct cause of the following exception:

Traceback (most recent call last):
  File "/home/runner/.local/lib/python3.12/site-packages/elastic_transport/_transport.py", line 344, in perform_request
    resp = node.perform_request(
           ^^^^^^^^^^^^^^^^^^^^^
  File "/home/runner/.local/lib/python3.12/site-packages/elastic_transport/_node/_http_urllib3.py", line 202, in perform_request
    raise err from e
elastic_transport.ConnectionError: Connection error caused by: NewConnectionError(<urllib3.connection.HTTPConnection object at 0x7f3378ba5100>: Failed to establish a new connection: [Errno 111] Connection refused)
2025-08-02 15:26:36,341 - elastic_transport.transport - INFO - HEAD http://localhost:9200/ [status:N/A duration:0.000s]
2025-08-02 15:26:36,341 - elastic_transport.node_pool - WARNING - Node <Urllib3HttpNode(http://localhost:9200)> has failed for 6 times in a row, putting on 30 second timeout
2025-08-02 15:26:36,341 - elastic_transport.transport - WARNING - Retrying request after failure (attempt 1 of 3)
Traceback (most recent call last):
  File "/usr/lib/python3/dist-packages/urllib3/connection.py", line 203, in _new_conn
    sock = connection.create_connection(
           ^^^^^^^^^^^^^^^^^^^^^^^^^^^^^
  File "/usr/lib/python3/dist-packages/urllib3/util/connection.py", line 85, in create_connection
    raise err
  File "/usr/lib/python3/dist-packages/urllib3/util/connection.py", line 73, in create_connection
    sock.connect(sa)
ConnectionRefusedError: [Errno 111] Connection refused

The above exception was the direct cause of the following exception:

Traceback (most recent call last):
  File "/home/runner/.local/lib/python3.12/site-packages/elastic_transport/_node/_http_urllib3.py", line 167, in perform_request
    response = self.pool.urlopen(
               ^^^^^^^^^^^^^^^^^^
  File "/usr/lib/python3/dist-packages/urllib3/connectionpool.py", line 845, in urlopen
    retries = retries.increment(
              ^^^^^^^^^^^^^^^^^^
  File "/usr/lib/python3/dist-packages/urllib3/util/retry.py", line 447, in increment
    raise reraise(type(error), error, _stacktrace)
          ^^^^^^^^^^^^^^^^^^^^^^^^^^^^^^^^^^^^^^^^
  File "/usr/lib/python3/dist-packages/urllib3/util/util.py", line 39, in reraise
    raise value
  File "/usr/lib/python3/dist-packages/urllib3/connectionpool.py", line 791, in urlopen
    response = self._make_request(
               ^^^^^^^^^^^^^^^^^^^
  File "/usr/lib/python3/dist-packages/urllib3/connectionpool.py", line 497, in _make_request
    conn.request(
  File "/usr/lib/python3/dist-packages/urllib3/connection.py", line 395, in request
    self.endheaders()
  File "/usr/lib/python3.12/http/client.py", line 1331, in endheaders
    self._send_output(message_body, encode_chunked=encode_chunked)
  File "/usr/lib/python3.12/http/client.py", line 1091, in _send_output
    self.send(msg)
  File "/usr/lib/python3.12/http/client.py", line 1035, in send
    self.connect()
  File "/usr/lib/python3/dist-packages/urllib3/connection.py", line 243, in connect
    self.sock = self._new_conn()
                ^^^^^^^^^^^^^^^^
  File "/usr/lib/python3/dist-packages/urllib3/connection.py", line 218, in _new_conn
    raise NewConnectionError(
urllib3.exceptions.NewConnectionError: <urllib3.connection.HTTPConnection object at 0x7f3378ba5b20>: Failed to establish a new connection: [Errno 111] Connection refused

The above exception was the direct cause of the following exception:

Traceback (most recent call last):
  File "/home/runner/.local/lib/python3.12/site-packages/elastic_transport/_transport.py", line 344, in perform_request
    resp = node.perform_request(
           ^^^^^^^^^^^^^^^^^^^^^
  File "/home/runner/.local/lib/python3.12/site-packages/elastic_transport/_node/_http_urllib3.py", line 202, in perform_request
    raise err from e
elastic_transport.ConnectionError: Connection error caused by: NewConnectionError(<urllib3.connection.HTTPConnection object at 0x7f3378ba5b20>: Failed to establish a new connection: [Errno 111] Connection refused)
2025-08-02 15:26:36,343 - elastic_transport.transport - INFO - HEAD http://localhost:9200/ [status:N/A duration:0.000s]
2025-08-02 15:26:36,343 - elastic_transport.node_pool - WARNING - Node <Urllib3HttpNode(http://localhost:9200)> has failed for 7 times in a row, putting on 30 second timeout
2025-08-02 15:26:36,343 - elastic_transport.transport - WARNING - Retrying request after failure (attempt 2 of 3)
Traceback (most recent call last):
  File "/usr/lib/python3/dist-packages/urllib3/connection.py", line 203, in _new_conn
    sock = connection.create_connection(
           ^^^^^^^^^^^^^^^^^^^^^^^^^^^^^
  File "/usr/lib/python3/dist-packages/urllib3/util/connection.py", line 85, in create_connection
    raise err
  File "/usr/lib/python3/dist-packages/urllib3/util/connection.py", line 73, in create_connection
    sock.connect(sa)
ConnectionRefusedError: [Errno 111] Connection refused

The above exception was the direct cause of the following exception:

Traceback (most recent call last):
  File "/home/runner/.local/lib/python3.12/site-packages/elastic_transport/_node/_http_urllib3.py", line 167, in perform_request
    response = self.pool.urlopen(
               ^^^^^^^^^^^^^^^^^^
  File "/usr/lib/python3/dist-packages/urllib3/connectionpool.py", line 845, in urlopen
    retries = retries.increment(
              ^^^^^^^^^^^^^^^^^^
  File "/usr/lib/python3/dist-packages/urllib3/util/retry.py", line 447, in increment
    raise reraise(type(error), error, _stacktrace)
          ^^^^^^^^^^^^^^^^^^^^^^^^^^^^^^^^^^^^^^^^
  File "/usr/lib/python3/dist-packages/urllib3/util/util.py", line 39, in reraise
    raise value
  File "/usr/lib/python3/dist-packages/urllib3/connectionpool.py", line 791, in urlopen
    response = self._make_request(
               ^^^^^^^^^^^^^^^^^^^
  File "/usr/lib/python3/dist-packages/urllib3/connectionpool.py", line 497, in _make_request
    conn.request(
  File "/usr/lib/python3/dist-packages/urllib3/connection.py", line 395, in request
    self.endheaders()
  File "/usr/lib/python3.12/http/client.py", line 1331, in endheaders
    self._send_output(message_body, encode_chunked=encode_chunked)
  File "/usr/lib/python3.12/http/client.py", line 1091, in _send_output
    self.send(msg)
  File "/usr/lib/python3.12/http/client.py", line 1035, in send
    self.connect()
  File "/usr/lib/python3/dist-packages/urllib3/connection.py", line 243, in connect
    self.sock = self._new_conn()
                ^^^^^^^^^^^^^^^^
  File "/usr/lib/python3/dist-packages/urllib3/connection.py", line 218, in _new_conn
    raise NewConnectionError(
urllib3.exceptions.NewConnectionError: <urllib3.connection.HTTPConnection object at 0x7f3378ba5820>: Failed to establish a new connection: [Errno 111] Connection refused

The above exception was the direct cause of the following exception:

Traceback (most recent call last):
  File "/home/runner/.local/lib/python3.12/site-packages/elastic_transport/_transport.py", line 344, in perform_request
    resp = node.perform_request(
           ^^^^^^^^^^^^^^^^^^^^^
  File "/home/runner/.local/lib/python3.12/site-packages/elastic_transport/_node/_http_urllib3.py", line 202, in perform_request
    raise err from e
elastic_transport.ConnectionError: Connection error caused by: NewConnectionError(<urllib3.connection.HTTPConnection object at 0x7f3378ba5820>: Failed to establish a new connection: [Errno 111] Connection refused)
2025-08-02 15:26:36,345 - elastic_transport.transport - INFO - HEAD http://localhost:9200/ [status:N/A duration:0.000s]
2025-08-02 15:26:36,345 - elastic_transport.node_pool - WARNING - Node <Urllib3HttpNode(http://localhost:9200)> has failed for 8 times in a row, putting on 30 second timeout
2025-08-02 15:26:36,345 - src.pipeline.pipeline_processor - INFO - ✓ format_detector: OK
2025-08-02 15:26:36,345 - src.pipeline.pipeline_processor - WARNING - ✗ ocr_processor: tesseract is not installed or it's not in your PATH. See README file for more information.
2025-08-02 15:26:36,345 - src.pipeline.pipeline_processor - INFO - ✓ text_extractor: OK
2025-08-02 15:26:36,345 - src.pipeline.pipeline_processor - INFO - ✓ classifier: OK
2025-08-02 15:26:36,345 - src.pipeline.pipeline_processor - WARNING - ✗ elasticsearch: Cannot reach Elasticsearch
2025-08-02 15:26:36,345 - src.pipeline.pipeline_processor - INFO - Setting up default classifier with sample data...
2025-08-02 15:26:36,348 - src.pipeline.classifier - ERROR - Error training model: The test_size = 6 should be greater or equal to the number of classes = 10
2025-08-02 15:26:36,348 - src.pipeline.pipeline_processor - ERROR - Failed to train default classifier: The test_size = 6 should be greater or equal to the number of classes = 10
2025-08-02 15:26:36,348 - src.pipeline.pipeline_processor - INFO - Pipeline system started successfully
2025-08-02 15:26:36,358 - werkzeug - INFO - [31m[1mWARNING: This is a development server. Do not use it in a production deployment. Use a production WSGI server instead.[0m
 * Running on all addresses (0.0.0.0)
 * Running on http://127.0.0.1:5001
 * Running on http://10.1.0.139:5001
2025-08-02 15:26:36,358 - werkzeug - INFO - [33mPress CTRL+C to quit[0m
2025-08-02 15:26:36,358 - werkzeug - INFO -  * Restarting with watchdog (inotify)
2025-08-02 15:26:37,734 - src.pipeline.classifier - INFO - No saved model found, will need to train
2025-08-02 15:26:37,735 - elastic_transport.transport - INFO - HEAD http://localhost:9200/ [status:N/A duration:0.001s]
2025-08-02 15:26:37,735 - elastic_transport.node_pool - WARNING - Node <Urllib3HttpNode(http://localhost:9200)> has failed for 1 times in a row, putting on 1 second timeout
2025-08-02 15:26:37,735 - elastic_transport.transport - WARNING - Retrying request after failure (attempt 0 of 3)
Traceback (most recent call last):
  File "/usr/lib/python3/dist-packages/urllib3/connection.py", line 203, in _new_conn
    sock = connection.create_connection(
           ^^^^^^^^^^^^^^^^^^^^^^^^^^^^^
  File "/usr/lib/python3/dist-packages/urllib3/util/connection.py", line 85, in create_connection
    raise err
  File "/usr/lib/python3/dist-packages/urllib3/util/connection.py", line 73, in create_connection
    sock.connect(sa)
ConnectionRefusedError: [Errno 111] Connection refused

The above exception was the direct cause of the following exception:

Traceback (most recent call last):
  File "/home/runner/.local/lib/python3.12/site-packages/elastic_transport/_node/_http_urllib3.py", line 167, in perform_request
    response = self.pool.urlopen(
               ^^^^^^^^^^^^^^^^^^
  File "/usr/lib/python3/dist-packages/urllib3/connectionpool.py", line 845, in urlopen
    retries = retries.increment(
              ^^^^^^^^^^^^^^^^^^
  File "/usr/lib/python3/dist-packages/urllib3/util/retry.py", line 447, in increment
    raise reraise(type(error), error, _stacktrace)
          ^^^^^^^^^^^^^^^^^^^^^^^^^^^^^^^^^^^^^^^^
  File "/usr/lib/python3/dist-packages/urllib3/util/util.py", line 39, in reraise
    raise value
  File "/usr/lib/python3/dist-packages/urllib3/connectionpool.py", line 791, in urlopen
    response = self._make_request(
               ^^^^^^^^^^^^^^^^^^^
  File "/usr/lib/python3/dist-packages/urllib3/connectionpool.py", line 497, in _make_request
    conn.request(
  File "/usr/lib/python3/dist-packages/urllib3/connection.py", line 395, in request
    self.endheaders()
  File "/usr/lib/python3.12/http/client.py", line 1331, in endheaders
    self._send_output(message_body, encode_chunked=encode_chunked)
  File "/usr/lib/python3.12/http/client.py", line 1091, in _send_output
    self.send(msg)
  File "/usr/lib/python3.12/http/client.py", line 1035, in send
    self.connect()
  File "/usr/lib/python3/dist-packages/urllib3/connection.py", line 243, in connect
    self.sock = self._new_conn()
                ^^^^^^^^^^^^^^^^
  File "/usr/lib/python3/dist-packages/urllib3/connection.py", line 218, in _new_conn
    raise NewConnectionError(
urllib3.exceptions.NewConnectionError: <urllib3.connection.HTTPConnection object at 0x7fbbf50a3380>: Failed to establish a new connection: [Errno 111] Connection refused

The above exception was the direct cause of the following exception:

Traceback (most recent call last):
  File "/home/runner/.local/lib/python3.12/site-packages/elastic_transport/_transport.py", line 344, in perform_request
    resp = node.perform_request(
           ^^^^^^^^^^^^^^^^^^^^^
  File "/home/runner/.local/lib/python3.12/site-packages/elastic_transport/_node/_http_urllib3.py", line 202, in perform_request
    raise err from e
elastic_transport.ConnectionError: Connection error caused by: NewConnectionError(<urllib3.connection.HTTPConnection object at 0x7fbbf50a3380>: Failed to establish a new connection: [Errno 111] Connection refused)
2025-08-02 15:26:37,738 - elastic_transport.transport - INFO - HEAD http://localhost:9200/ [status:N/A duration:0.000s]
2025-08-02 15:26:37,738 - elastic_transport.node_pool - WARNING - Node <Urllib3HttpNode(http://localhost:9200)> has failed for 2 times in a row, putting on 2 second timeout
2025-08-02 15:26:37,738 - elastic_transport.transport - WARNING - Retrying request after failure (attempt 1 of 3)
Traceback (most recent call last):
  File "/usr/lib/python3/dist-packages/urllib3/connection.py", line 203, in _new_conn
    sock = connection.create_connection(
           ^^^^^^^^^^^^^^^^^^^^^^^^^^^^^
  File "/usr/lib/python3/dist-packages/urllib3/util/connection.py", line 85, in create_connection
    raise err
  File "/usr/lib/python3/dist-packages/urllib3/util/connection.py", line 73, in create_connection
    sock.connect(sa)
ConnectionRefusedError: [Errno 111] Connection refused

The above exception was the direct cause of the following exception:

Traceback (most recent call last):
  File "/home/runner/.local/lib/python3.12/site-packages/elastic_transport/_node/_http_urllib3.py", line 167, in perform_request
    response = self.pool.urlopen(
               ^^^^^^^^^^^^^^^^^^
  File "/usr/lib/python3/dist-packages/urllib3/connectionpool.py", line 845, in urlopen
    retries = retries.increment(
              ^^^^^^^^^^^^^^^^^^
  File "/usr/lib/python3/dist-packages/urllib3/util/retry.py", line 447, in increment
    raise reraise(type(error), error, _stacktrace)
          ^^^^^^^^^^^^^^^^^^^^^^^^^^^^^^^^^^^^^^^^
  File "/usr/lib/python3/dist-packages/urllib3/util/util.py", line 39, in reraise
    raise value
  File "/usr/lib/python3/dist-packages/urllib3/connectionpool.py", line 791, in urlopen
    response = self._make_request(
               ^^^^^^^^^^^^^^^^^^^
  File "/usr/lib/python3/dist-packages/urllib3/connectionpool.py", line 497, in _make_request
    conn.request(
  File "/usr/lib/python3/dist-packages/urllib3/connection.py", line 395, in request
    self.endheaders()
  File "/usr/lib/python3.12/http/client.py", line 1331, in endheaders
    self._send_output(message_body, encode_chunked=encode_chunked)
  File "/usr/lib/python3.12/http/client.py", line 1091, in _send_output
    self.send(msg)
  File "/usr/lib/python3.12/http/client.py", line 1035, in send
    self.connect()
  File "/usr/lib/python3/dist-packages/urllib3/connection.py", line 243, in connect
    self.sock = self._new_conn()
                ^^^^^^^^^^^^^^^^
  File "/usr/lib/python3/dist-packages/urllib3/connection.py", line 218, in _new_conn
    raise NewConnectionError(
urllib3.exceptions.NewConnectionError: <urllib3.connection.HTTPConnection object at 0x7fbbf527e3c0>: Failed to establish a new connection: [Errno 111] Connection refused

The above exception was the direct cause of the following exception:

Traceback (most recent call last):
  File "/home/runner/.local/lib/python3.12/site-packages/elastic_transport/_transport.py", line 344, in perform_request
    resp = node.perform_request(
           ^^^^^^^^^^^^^^^^^^^^^
  File "/home/runner/.local/lib/python3.12/site-packages/elastic_transport/_node/_http_urllib3.py", line 202, in perform_request
    raise err from e
elastic_transport.ConnectionError: Connection error caused by: NewConnectionError(<urllib3.connection.HTTPConnection object at 0x7fbbf527e3c0>: Failed to establish a new connection: [Errno 111] Connection refused)
2025-08-02 15:26:37,740 - elastic_transport.transport - INFO - HEAD http://localhost:9200/ [status:N/A duration:0.000s]
2025-08-02 15:26:37,740 - elastic_transport.node_pool - WARNING - Node <Urllib3HttpNode(http://localhost:9200)> has failed for 3 times in a row, putting on 4 second timeout
2025-08-02 15:26:37,740 - elastic_transport.transport - WARNING - Retrying request after failure (attempt 2 of 3)
Traceback (most recent call last):
  File "/usr/lib/python3/dist-packages/urllib3/connection.py", line 203, in _new_conn
    sock = connection.create_connection(
           ^^^^^^^^^^^^^^^^^^^^^^^^^^^^^
  File "/usr/lib/python3/dist-packages/urllib3/util/connection.py", line 85, in create_connection
    raise err
  File "/usr/lib/python3/dist-packages/urllib3/util/connection.py", line 73, in create_connection
    sock.connect(sa)
ConnectionRefusedError: [Errno 111] Connection refused

The above exception was the direct cause of the following exception:

Traceback (most recent call last):
  File "/home/runner/.local/lib/python3.12/site-packages/elastic_transport/_node/_http_urllib3.py", line 167, in perform_request
    response = self.pool.urlopen(
               ^^^^^^^^^^^^^^^^^^
  File "/usr/lib/python3/dist-packages/urllib3/connectionpool.py", line 845, in urlopen
    retries = retries.increment(
              ^^^^^^^^^^^^^^^^^^
  File "/usr/lib/python3/dist-packages/urllib3/util/retry.py", line 447, in increment
    raise reraise(type(error), error, _stacktrace)
          ^^^^^^^^^^^^^^^^^^^^^^^^^^^^^^^^^^^^^^^^
  File "/usr/lib/python3/dist-packages/urllib3/util/util.py", line 39, in reraise
    raise value
  File "/usr/lib/python3/dist-packages/urllib3/connectionpool.py", line 791, in urlopen
    response = self._make_request(
               ^^^^^^^^^^^^^^^^^^^
  File "/usr/lib/python3/dist-packages/urllib3/connectionpool.py", line 497, in _make_request
    conn.request(
  File "/usr/lib/python3/dist-packages/urllib3/connection.py", line 395, in request
    self.endheaders()
  File "/usr/lib/python3.12/http/client.py", line 1331, in endheaders
    self._send_output(message_body, encode_chunked=encode_chunked)
  File "/usr/lib/python3.12/http/client.py", line 1091, in _send_output
    self.send(msg)
  File "/usr/lib/python3.12/http/client.py", line 1035, in send
    self.connect()
  File "/usr/lib/python3/dist-packages/urllib3/connection.py", line 243, in connect
    self.sock = self._new_conn()
                ^^^^^^^^^^^^^^^^
  File "/usr/lib/python3/dist-packages/urllib3/connection.py", line 218, in _new_conn
    raise NewConnectionError(
urllib3.exceptions.NewConnectionError: <urllib3.connection.HTTPConnection object at 0x7fbbf50ca6c0>: Failed to establish a new connection: [Errno 111] Connection refused

The above exception was the direct cause of the following exception:

Traceback (most recent call last):
  File "/home/runner/.local/lib/python3.12/site-packages/elastic_transport/_transport.py", line 344, in perform_request
    resp = node.perform_request(
           ^^^^^^^^^^^^^^^^^^^^^
  File "/home/runner/.local/lib/python3.12/site-packages/elastic_transport/_node/_http_urllib3.py", line 202, in perform_request
    raise err from e
elastic_transport.ConnectionError: Connection error caused by: NewConnectionError(<urllib3.connection.HTTPConnection object at 0x7fbbf50ca6c0>: Failed to establish a new connection: [Errno 111] Connection refused)
2025-08-02 15:26:37,742 - elastic_transport.transport - INFO - HEAD http://localhost:9200/ [status:N/A duration:0.000s]
2025-08-02 15:26:37,742 - elastic_transport.node_pool - WARNING - Node <Urllib3HttpNode(http://localhost:9200)> has failed for 4 times in a row, putting on 8 second timeout
2025-08-02 15:26:37,742 - src.pipeline.elasticsearch_indexer - ERROR - Cannot connect to Elasticsearch at http://localhost:9200
2025-08-02 15:26:37,742 - src.pipeline.pipeline_processor - INFO - Pipeline processor initialized
2025-08-02 15:26:37,742 - src.pipeline.pipeline_processor - INFO - Pipeline manager initialized
2025-08-02 15:26:37,742 - src.pipeline.pipeline_processor - INFO - Starting PDF processing pipeline...
2025-08-02 15:26:37,743 - src.pipeline.ocr_processor - ERROR - Tesseract installation test failed: tesseract is not installed or it's not in your PATH. See README file for more information.
2025-08-02 15:26:37,743 - elastic_transport.transport - INFO - HEAD http://localhost:9200/ [status:N/A duration:0.000s]
2025-08-02 15:26:37,743 - elastic_transport.node_pool - WARNING - Node <Urllib3HttpNode(http://localhost:9200)> has failed for 5 times in a row, putting on 16 second timeout
2025-08-02 15:26:37,743 - elastic_transport.transport - WARNING - Retrying request after failure (attempt 0 of 3)
Traceback (most recent call last):
  File "/usr/lib/python3/dist-packages/urllib3/connection.py", line 203, in _new_conn
    sock = connection.create_connection(
           ^^^^^^^^^^^^^^^^^^^^^^^^^^^^^
  File "/usr/lib/python3/dist-packages/urllib3/util/connection.py", line 85, in create_connection
    raise err
  File "/usr/lib/python3/dist-packages/urllib3/util/connection.py", line 73, in create_connection
    sock.connect(sa)
ConnectionRefusedError: [Errno 111] Connection refused

The above exception was the direct cause of the following exception:

Traceback (most recent call last):
  File "/home/runner/.local/lib/python3.12/site-packages/elastic_transport/_node/_http_urllib3.py", line 167, in perform_request
    response = self.pool.urlopen(
               ^^^^^^^^^^^^^^^^^^
  File "/usr/lib/python3/dist-packages/urllib3/connectionpool.py", line 845, in urlopen
    retries = retries.increment(
              ^^^^^^^^^^^^^^^^^^
  File "/usr/lib/python3/dist-packages/urllib3/util/retry.py", line 447, in increment
    raise reraise(type(error), error, _stacktrace)
          ^^^^^^^^^^^^^^^^^^^^^^^^^^^^^^^^^^^^^^^^
  File "/usr/lib/python3/dist-packages/urllib3/util/util.py", line 39, in reraise
    raise value
  File "/usr/lib/python3/dist-packages/urllib3/connectionpool.py", line 791, in urlopen
    response = self._make_request(
               ^^^^^^^^^^^^^^^^^^^
  File "/usr/lib/python3/dist-packages/urllib3/connectionpool.py", line 497, in _make_request
    conn.request(
  File "/usr/lib/python3/dist-packages/urllib3/connection.py", line 395, in request
    self.endheaders()
  File "/usr/lib/python3.12/http/client.py", line 1331, in endheaders
    self._send_output(message_body, encode_chunked=encode_chunked)
  File "/usr/lib/python3.12/http/client.py", line 1091, in _send_output
    self.send(msg)
  File "/usr/lib/python3.12/http/client.py", line 1035, in send
    self.connect()
  File "/usr/lib/python3/dist-packages/urllib3/connection.py", line 243, in connect
    self.sock = self._new_conn()
                ^^^^^^^^^^^^^^^^
  File "/usr/lib/python3/dist-packages/urllib3/connection.py", line 218, in _new_conn
    raise NewConnectionError(
urllib3.exceptions.NewConnectionError: <urllib3.connection.HTTPConnection object at 0x7fbbf50cacf0>: Failed to establish a new connection: [Errno 111] Connection refused

The above exception was the direct cause of the following exception:

Traceback (most recent call last):
  File "/home/runner/.local/lib/python3.12/site-packages/elastic_transport/_transport.py", line 344, in perform_request
    resp = node.perform_request(
           ^^^^^^^^^^^^^^^^^^^^^
  File "/home/runner/.local/lib/python3.12/site-packages/elastic_transport/_node/_http_urllib3.py", line 202, in perform_request
    raise err from e
elastic_transport.ConnectionError: Connection error caused by: NewConnectionError(<urllib3.connection.HTTPConnection object at 0x7fbbf50cacf0>: Failed to establish a new connection: [Errno 111] Connection refused)
2025-08-02 15:26:37,745 - elastic_transport.transport - INFO - HEAD http://localhost:9200/ [status:N/A duration:0.000s]
2025-08-02 15:26:37,745 - elastic_transport.node_pool - WARNING - Node <Urllib3HttpNode(http://localhost:9200)> has failed for 6 times in a row, putting on 30 second timeout
2025-08-02 15:26:37,745 - elastic_transport.transport - WARNING - Retrying request after failure (attempt 1 of 3)
Traceback (most recent call last):
  File "/usr/lib/python3/dist-packages/urllib3/connection.py", line 203, in _new_conn
    sock = connection.create_connection(
           ^^^^^^^^^^^^^^^^^^^^^^^^^^^^^
  File "/usr/lib/python3/dist-packages/urllib3/util/connection.py", line 85, in create_connection
    raise err
  File "/usr/lib/python3/dist-packages/urllib3/util/connection.py", line 73, in create_connection
    sock.connect(sa)
ConnectionRefusedError: [Errno 111] Connection refused

The above exception was the direct cause of the following exception:

Traceback (most recent call last):
  File "/home/runner/.local/lib/python3.12/site-packages/elastic_transport/_node/_http_urllib3.py", line 167, in perform_request
    response = self.pool.urlopen(
               ^^^^^^^^^^^^^^^^^^
  File "/usr/lib/python3/dist-packages/urllib3/connectionpool.py", line 845, in urlopen
    retries = retries.increment(
              ^^^^^^^^^^^^^^^^^^
  File "/usr/lib/python3/dist-packages/urllib3/util/retry.py", line 447, in increment
    raise reraise(type(error), error, _stacktrace)
          ^^^^^^^^^^^^^^^^^^^^^^^^^^^^^^^^^^^^^^^^
  File "/usr/lib/python3/dist-packages/urllib3/util/util.py", line 39, in reraise
    raise value
  File "/usr/lib/python3/dist-packages/urllib3/connectionpool.py", line 791, in urlopen
    response = self._make_request(
               ^^^^^^^^^^^^^^^^^^^
  File "/usr/lib/python3/dist-packages/urllib3/connectionpool.py", line 497, in _make_request
    conn.request(
  File "/usr/lib/python3/dist-packages/urllib3/connection.py", line 395, in request
    self.endheaders()
  File "/usr/lib/python3.12/http/client.py", line 1331, in endheaders
    self._send_output(message_body, encode_chunked=encode_chunked)
  File "/usr/lib/python3.12/http/client.py", line 1091, in _send_output
    self.send(msg)
  File "/usr/lib/python3.12/http/client.py", line 1035, in send
    self.connect()
  File "/usr/lib/python3/dist-packages/urllib3/connection.py", line 243, in connect
    self.sock = self._new_conn()
                ^^^^^^^^^^^^^^^^
  File "/usr/lib/python3/dist-packages/urllib3/connection.py", line 218, in _new_conn
    raise NewConnectionError(
urllib3.exceptions.NewConnectionError: <urllib3.connection.HTTPConnection object at 0x7fbbf50cb2f0>: Failed to establish a new connection: [Errno 111] Connection refused

The above exception was the direct cause of the following exception:

Traceback (most recent call last):
  File "/home/runner/.local/lib/python3.12/site-packages/elastic_transport/_transport.py", line 344, in perform_request
    resp = node.perform_request(
           ^^^^^^^^^^^^^^^^^^^^^
  File "/home/runner/.local/lib/python3.12/site-packages/elastic_transport/_node/_http_urllib3.py", line 202, in perform_request
    raise err from e
elastic_transport.ConnectionError: Connection error caused by: NewConnectionError(<urllib3.connection.HTTPConnection object at 0x7fbbf50cb2f0>: Failed to establish a new connection: [Errno 111] Connection refused)
2025-08-02 15:26:37,746 - elastic_transport.transport - INFO - HEAD http://localhost:9200/ [status:N/A duration:0.000s]
2025-08-02 15:26:37,746 - elastic_transport.node_pool - WARNING - Node <Urllib3HttpNode(http://localhost:9200)> has failed for 7 times in a row, putting on 30 second timeout
2025-08-02 15:26:37,746 - elastic_transport.transport - WARNING - Retrying request after failure (attempt 2 of 3)
Traceback (most recent call last):
  File "/usr/lib/python3/dist-packages/urllib3/connection.py", line 203, in _new_conn
    sock = connection.create_connection(
           ^^^^^^^^^^^^^^^^^^^^^^^^^^^^^
  File "/usr/lib/python3/dist-packages/urllib3/util/connection.py", line 85, in create_connection
    raise err
  File "/usr/lib/python3/dist-packages/urllib3/util/connection.py", line 73, in create_connection
    sock.connect(sa)
ConnectionRefusedError: [Errno 111] Connection refused

The above exception was the direct cause of the following exception:

Traceback (most recent call last):
  File "/home/runner/.local/lib/python3.12/site-packages/elastic_transport/_node/_http_urllib3.py", line 167, in perform_request
    response = self.pool.urlopen(
               ^^^^^^^^^^^^^^^^^^
  File "/usr/lib/python3/dist-packages/urllib3/connectionpool.py", line 845, in urlopen
    retries = retries.increment(
              ^^^^^^^^^^^^^^^^^^
  File "/usr/lib/python3/dist-packages/urllib3/util/retry.py", line 447, in increment
    raise reraise(type(error), error, _stacktrace)
          ^^^^^^^^^^^^^^^^^^^^^^^^^^^^^^^^^^^^^^^^
  File "/usr/lib/python3/dist-packages/urllib3/util/util.py", line 39, in reraise
    raise value
  File "/usr/lib/python3/dist-packages/urllib3/connectionpool.py", line 791, in urlopen
    response = self._make_request(
               ^^^^^^^^^^^^^^^^^^^
  File "/usr/lib/python3/dist-packages/urllib3/connectionpool.py", line 497, in _make_request
    conn.request(
  File "/usr/lib/python3/dist-packages/urllib3/connection.py", line 395, in request
    self.endheaders()
  File "/usr/lib/python3.12/http/client.py", line 1331, in endheaders
    self._send_output(message_body, encode_chunked=encode_chunked)
  File "/usr/lib/python3.12/http/client.py", line 1091, in _send_output
    self.send(msg)
  File "/usr/lib/python3.12/http/client.py", line 1035, in send
    self.connect()
  File "/usr/lib/python3/dist-packages/urllib3/connection.py", line 243, in connect
    self.sock = self._new_conn()
                ^^^^^^^^^^^^^^^^
  File "/usr/lib/python3/dist-packages/urllib3/connection.py", line 218, in _new_conn
    raise NewConnectionError(
urllib3.exceptions.NewConnectionError: <urllib3.connection.HTTPConnection object at 0x7fbbf50cb230>: Failed to establish a new connection: [Errno 111] Connection refused

The above exception was the direct cause of the following exception:

Traceback (most recent call last):
  File "/home/runner/.local/lib/python3.12/site-packages/elastic_transport/_transport.py", line 344, in perform_request
    resp = node.perform_request(
           ^^^^^^^^^^^^^^^^^^^^^
  File "/home/runner/.local/lib/python3.12/site-packages/elastic_transport/_node/_http_urllib3.py", line 202, in perform_request
    raise err from e
elastic_transport.ConnectionError: Connection error caused by: NewConnectionError(<urllib3.connection.HTTPConnection object at 0x7fbbf50cb230>: Failed to establish a new connection: [Errno 111] Connection refused)
2025-08-02 15:26:37,747 - elastic_transport.transport - INFO - HEAD http://localhost:9200/ [status:N/A duration:0.000s]
2025-08-02 15:26:37,748 - elastic_transport.node_pool - WARNING - Node <Urllib3HttpNode(http://localhost:9200)> has failed for 8 times in a row, putting on 30 second timeout
2025-08-02 15:26:37,748 - src.pipeline.pipeline_processor - INFO - ✓ format_detector: OK
2025-08-02 15:26:37,748 - src.pipeline.pipeline_processor - WARNING - ✗ ocr_processor: tesseract is not installed or it's not in your PATH. See README file for more information.
2025-08-02 15:26:37,748 - src.pipeline.pipeline_processor - INFO - ✓ text_extractor: OK
2025-08-02 15:26:37,748 - src.pipeline.pipeline_processor - INFO - ✓ classifier: OK
2025-08-02 15:26:37,748 - src.pipeline.pipeline_processor - WARNING - ✗ elasticsearch: Cannot reach Elasticsearch
2025-08-02 15:26:37,748 - src.pipeline.pipeline_processor - INFO - Setting up default classifier with sample data...
2025-08-02 15:26:37,750 - src.pipeline.classifier - ERROR - Error training model: The test_size = 6 should be greater or equal to the number of classes = 10
2025-08-02 15:26:37,750 - src.pipeline.pipeline_processor - ERROR - Failed to train default classifier: The test_size = 6 should be greater or equal to the number of classes = 10
2025-08-02 15:26:37,750 - src.pipeline.pipeline_processor - INFO - Pipeline system started successfully
2025-08-02 15:26:37,759 - src.pipeline.classifier - INFO - No saved model found, will need to train
2025-08-02 15:26:37,760 - elastic_transport.transport - INFO - HEAD http://localhost:9200/ [status:N/A duration:0.000s]
2025-08-02 15:26:37,760 - elastic_transport.node_pool - WARNING - Node <Urllib3HttpNode(http://localhost:9200)> has failed for 1 times in a row, putting on 1 second timeout
2025-08-02 15:26:37,760 - elastic_transport.transport - WARNING - Retrying request after failure (attempt 0 of 3)
Traceback (most recent call last):
  File "/usr/lib/python3/dist-packages/urllib3/connection.py", line 203, in _new_conn
    sock = connection.create_connection(
           ^^^^^^^^^^^^^^^^^^^^^^^^^^^^^
  File "/usr/lib/python3/dist-packages/urllib3/util/connection.py", line 85, in create_connection
    raise err
  File "/usr/lib/python3/dist-packages/urllib3/util/connection.py", line 73, in create_connection
    sock.connect(sa)
ConnectionRefusedError: [Errno 111] Connection refused

The above exception was the direct cause of the following exception:

Traceback (most recent call last):
  File "/home/runner/.local/lib/python3.12/site-packages/elastic_transport/_node/_http_urllib3.py", line 167, in perform_request
    response = self.pool.urlopen(
               ^^^^^^^^^^^^^^^^^^
  File "/usr/lib/python3/dist-packages/urllib3/connectionpool.py", line 845, in urlopen
    retries = retries.increment(
              ^^^^^^^^^^^^^^^^^^
  File "/usr/lib/python3/dist-packages/urllib3/util/retry.py", line 447, in increment
    raise reraise(type(error), error, _stacktrace)
          ^^^^^^^^^^^^^^^^^^^^^^^^^^^^^^^^^^^^^^^^
  File "/usr/lib/python3/dist-packages/urllib3/util/util.py", line 39, in reraise
    raise value
  File "/usr/lib/python3/dist-packages/urllib3/connectionpool.py", line 791, in urlopen
    response = self._make_request(
               ^^^^^^^^^^^^^^^^^^^
  File "/usr/lib/python3/dist-packages/urllib3/connectionpool.py", line 497, in _make_request
    conn.request(
  File "/usr/lib/python3/dist-packages/urllib3/connection.py", line 395, in request
    self.endheaders()
  File "/usr/lib/python3.12/http/client.py", line 1331, in endheaders
    self._send_output(message_body, encode_chunked=encode_chunked)
  File "/usr/lib/python3.12/http/client.py", line 1091, in _send_output
    self.send(msg)
  File "/usr/lib/python3.12/http/client.py", line 1035, in send
    self.connect()
  File "/usr/lib/python3/dist-packages/urllib3/connection.py", line 243, in connect
    self.sock = self._new_conn()
                ^^^^^^^^^^^^^^^^
  File "/usr/lib/python3/dist-packages/urllib3/connection.py", line 218, in _new_conn
    raise NewConnectionError(
urllib3.exceptions.NewConnectionError: <urllib3.connection.HTTPConnection object at 0x7fbbf4fc8cb0>: Failed to establish a new connection: [Errno 111] Connection refused

The above exception was the direct cause of the following exception:

Traceback (most recent call last):
  File "/home/runner/.local/lib/python3.12/site-packages/elastic_transport/_transport.py", line 344, in perform_request
    resp = node.perform_request(
           ^^^^^^^^^^^^^^^^^^^^^
  File "/home/runner/.local/lib/python3.12/site-packages/elastic_transport/_node/_http_urllib3.py", line 202, in perform_request
    raise err from e
elastic_transport.ConnectionError: Connection error caused by: NewConnectionError(<urllib3.connection.HTTPConnection object at 0x7fbbf4fc8cb0>: Failed to establish a new connection: [Errno 111] Connection refused)
2025-08-02 15:26:37,761 - elastic_transport.transport - INFO - HEAD http://localhost:9200/ [status:N/A duration:0.000s]
2025-08-02 15:26:37,761 - elastic_transport.node_pool - WARNING - Node <Urllib3HttpNode(http://localhost:9200)> has failed for 2 times in a row, putting on 2 second timeout
2025-08-02 15:26:37,762 - elastic_transport.transport - WARNING - Retrying request after failure (attempt 1 of 3)
Traceback (most recent call last):
  File "/usr/lib/python3/dist-packages/urllib3/connection.py", line 203, in _new_conn
    sock = connection.create_connection(
           ^^^^^^^^^^^^^^^^^^^^^^^^^^^^^
  File "/usr/lib/python3/dist-packages/urllib3/util/connection.py", line 85, in create_connection
    raise err
  File "/usr/lib/python3/dist-packages/urllib3/util/connection.py", line 73, in create_connection
    sock.connect(sa)
ConnectionRefusedError: [Errno 111] Connection refused

The above exception was the direct cause of the following exception:

Traceback (most recent call last):
  File "/home/runner/.local/lib/python3.12/site-packages/elastic_transport/_node/_http_urllib3.py", line 167, in perform_request
    response = self.pool.urlopen(
               ^^^^^^^^^^^^^^^^^^
  File "/usr/lib/python3/dist-packages/urllib3/connectionpool.py", line 845, in urlopen
    retries = retries.increment(
              ^^^^^^^^^^^^^^^^^^
  File "/usr/lib/python3/dist-packages/urllib3/util/retry.py", line 447, in increment
    raise reraise(type(error), error, _stacktrace)
          ^^^^^^^^^^^^^^^^^^^^^^^^^^^^^^^^^^^^^^^^
  File "/usr/lib/python3/dist-packages/urllib3/util/util.py", line 39, in reraise
    raise value
  File "/usr/lib/python3/dist-packages/urllib3/connectionpool.py", line 791, in urlopen
    response = self._make_request(
               ^^^^^^^^^^^^^^^^^^^
  File "/usr/lib/python3/dist-packages/urllib3/connectionpool.py", line 497, in _make_request
    conn.request(
  File "/usr/lib/python3/dist-packages/urllib3/connection.py", line 395, in request
    self.endheaders()
  File "/usr/lib/python3.12/http/client.py", line 1331, in endheaders
    self._send_output(message_body, encode_chunked=encode_chunked)
  File "/usr/lib/python3.12/http/client.py", line 1091, in _send_output
    self.send(msg)
  File "/usr/lib/python3.12/http/client.py", line 1035, in send
    self.connect()
  File "/usr/lib/python3/dist-packages/urllib3/connection.py", line 243, in connect
    self.sock = self._new_conn()
                ^^^^^^^^^^^^^^^^
  File "/usr/lib/python3/dist-packages/urllib3/connection.py", line 218, in _new_conn
    raise NewConnectionError(
urllib3.exceptions.NewConnectionError: <urllib3.connection.HTTPConnection object at 0x7fbbf4fc8ec0>: Failed to establish a new connection: [Errno 111] Connection refused

The above exception was the direct cause of the following exception:

Traceback (most recent call last):
  File "/home/runner/.local/lib/python3.12/site-packages/elastic_transport/_transport.py", line 344, in perform_request
    resp = node.perform_request(
           ^^^^^^^^^^^^^^^^^^^^^
  File "/home/runner/.local/lib/python3.12/site-packages/elastic_transport/_node/_http_urllib3.py", line 202, in perform_request
    raise err from e
elastic_transport.ConnectionError: Connection error caused by: NewConnectionError(<urllib3.connection.HTTPConnection object at 0x7fbbf4fc8ec0>: Failed to establish a new connection: [Errno 111] Connection refused)
2025-08-02 15:26:37,763 - elastic_transport.transport - INFO - HEAD http://localhost:9200/ [status:N/A duration:0.000s]
2025-08-02 15:26:37,763 - elastic_transport.node_pool - WARNING - Node <Urllib3HttpNode(http://localhost:9200)> has failed for 3 times in a row, putting on 4 second timeout
2025-08-02 15:26:37,763 - elastic_transport.transport - WARNING - Retrying request after failure (attempt 2 of 3)
Traceback (most recent call last):
  File "/usr/lib/python3/dist-packages/urllib3/connection.py", line 203, in _new_conn
    sock = connection.create_connection(
           ^^^^^^^^^^^^^^^^^^^^^^^^^^^^^
  File "/usr/lib/python3/dist-packages/urllib3/util/connection.py", line 85, in create_connection
    raise err
  File "/usr/lib/python3/dist-packages/urllib3/util/connection.py", line 73, in create_connection
    sock.connect(sa)
ConnectionRefusedError: [Errno 111] Connection refused

The above exception was the direct cause of the following exception:

Traceback (most recent call last):
  File "/home/runner/.local/lib/python3.12/site-packages/elastic_transport/_node/_http_urllib3.py", line 167, in perform_request
    response = self.pool.urlopen(
               ^^^^^^^^^^^^^^^^^^
  File "/usr/lib/python3/dist-packages/urllib3/connectionpool.py", line 845, in urlopen
    retries = retries.increment(
              ^^^^^^^^^^^^^^^^^^
  File "/usr/lib/python3/dist-packages/urllib3/util/retry.py", line 447, in increment
    raise reraise(type(error), error, _stacktrace)
          ^^^^^^^^^^^^^^^^^^^^^^^^^^^^^^^^^^^^^^^^
  File "/usr/lib/python3/dist-packages/urllib3/util/util.py", line 39, in reraise
    raise value
  File "/usr/lib/python3/dist-packages/urllib3/connectionpool.py", line 791, in urlopen
    response = self._make_request(
               ^^^^^^^^^^^^^^^^^^^
  File "/usr/lib/python3/dist-packages/urllib3/connectionpool.py", line 497, in _make_request
    conn.request(
  File "/usr/lib/python3/dist-packages/urllib3/connection.py", line 395, in request
    self.endheaders()
  File "/usr/lib/python3.12/http/client.py", line 1331, in endheaders
    self._send_output(message_body, encode_chunked=encode_chunked)
  File "/usr/lib/python3.12/http/client.py", line 1091, in _send_output
    self.send(msg)
  File "/usr/lib/python3.12/http/client.py", line 1035, in send
    self.connect()
  File "/usr/lib/python3/dist-packages/urllib3/connection.py", line 243, in connect
    self.sock = self._new_conn()
                ^^^^^^^^^^^^^^^^
  File "/usr/lib/python3/dist-packages/urllib3/connection.py", line 218, in _new_conn
    raise NewConnectionError(
urllib3.exceptions.NewConnectionError: <urllib3.connection.HTTPConnection object at 0x7fbbf4fc8fb0>: Failed to establish a new connection: [Errno 111] Connection refused

The above exception was the direct cause of the following exception:

Traceback (most recent call last):
  File "/home/runner/.local/lib/python3.12/site-packages/elastic_transport/_transport.py", line 344, in perform_request
    resp = node.perform_request(
           ^^^^^^^^^^^^^^^^^^^^^
  File "/home/runner/.local/lib/python3.12/site-packages/elastic_transport/_node/_http_urllib3.py", line 202, in perform_request
    raise err from e
elastic_transport.ConnectionError: Connection error caused by: NewConnectionError(<urllib3.connection.HTTPConnection object at 0x7fbbf4fc8fb0>: Failed to establish a new connection: [Errno 111] Connection refused)
2025-08-02 15:26:37,764 - elastic_transport.transport - INFO - HEAD http://localhost:9200/ [status:N/A duration:0.000s]
2025-08-02 15:26:37,764 - elastic_transport.node_pool - WARNING - Node <Urllib3HttpNode(http://localhost:9200)> has failed for 4 times in a row, putting on 8 second timeout
2025-08-02 15:26:37,764 - src.pipeline.elasticsearch_indexer - ERROR - Cannot connect to Elasticsearch at http://localhost:9200
2025-08-02 15:26:37,765 - src.pipeline.pipeline_processor - INFO - Pipeline processor initialized
2025-08-02 15:26:37,765 - src.pipeline.pipeline_processor - INFO - Pipeline manager initialized
2025-08-02 15:26:37,765 - src.pipeline.pipeline_processor - INFO - Starting PDF processing pipeline...
2025-08-02 15:26:37,765 - src.pipeline.ocr_processor - ERROR - Tesseract installation test failed: tesseract is not installed or it's not in your PATH. See README file for more information.
2025-08-02 15:26:37,766 - elastic_transport.transport - INFO - HEAD http://localhost:9200/ [status:N/A duration:0.000s]
2025-08-02 15:26:37,766 - elastic_transport.node_pool - WARNING - Node <Urllib3HttpNode(http://localhost:9200)> has failed for 5 times in a row, putting on 16 second timeout
2025-08-02 15:26:37,766 - elastic_transport.transport - WARNING - Retrying request after failure (attempt 0 of 3)
Traceback (most recent call last):
  File "/usr/lib/python3/dist-packages/urllib3/connection.py", line 203, in _new_conn
    sock = connection.create_connection(
           ^^^^^^^^^^^^^^^^^^^^^^^^^^^^^
  File "/usr/lib/python3/dist-packages/urllib3/util/connection.py", line 85, in create_connection
    raise err
  File "/usr/lib/python3/dist-packages/urllib3/util/connection.py", line 73, in create_connection
    sock.connect(sa)
ConnectionRefusedError: [Errno 111] Connection refused

The above exception was the direct cause of the following exception:

Traceback (most recent call last):
  File "/home/runner/.local/lib/python3.12/site-packages/elastic_transport/_node/_http_urllib3.py", line 167, in perform_request
    response = self.pool.urlopen(
               ^^^^^^^^^^^^^^^^^^
  File "/usr/lib/python3/dist-packages/urllib3/connectionpool.py", line 845, in urlopen
    retries = retries.increment(
              ^^^^^^^^^^^^^^^^^^
  File "/usr/lib/python3/dist-packages/urllib3/util/retry.py", line 447, in increment
    raise reraise(type(error), error, _stacktrace)
          ^^^^^^^^^^^^^^^^^^^^^^^^^^^^^^^^^^^^^^^^
  File "/usr/lib/python3/dist-packages/urllib3/util/util.py", line 39, in reraise
    raise value
  File "/usr/lib/python3/dist-packages/urllib3/connectionpool.py", line 791, in urlopen
    response = self._make_request(
               ^^^^^^^^^^^^^^^^^^^
  File "/usr/lib/python3/dist-packages/urllib3/connectionpool.py", line 497, in _make_request
    conn.request(
  File "/usr/lib/python3/dist-packages/urllib3/connection.py", line 395, in request
    self.endheaders()
  File "/usr/lib/python3.12/http/client.py", line 1331, in endheaders
    self._send_output(message_body, encode_chunked=encode_chunked)
  File "/usr/lib/python3.12/http/client.py", line 1091, in _send_output
    self.send(msg)
  File "/usr/lib/python3.12/http/client.py", line 1035, in send
    self.connect()
  File "/usr/lib/python3/dist-packages/urllib3/connection.py", line 243, in connect
    self.sock = self._new_conn()
                ^^^^^^^^^^^^^^^^
  File "/usr/lib/python3/dist-packages/urllib3/connection.py", line 218, in _new_conn
    raise NewConnectionError(
urllib3.exceptions.NewConnectionError: <urllib3.connection.HTTPConnection object at 0x7fbbf4fc9280>: Failed to establish a new connection: [Errno 111] Connection refused

The above exception was the direct cause of the following exception:

Traceback (most recent call last):
  File "/home/runner/.local/lib/python3.12/site-packages/elastic_transport/_transport.py", line 344, in perform_request
    resp = node.perform_request(
           ^^^^^^^^^^^^^^^^^^^^^
  File "/home/runner/.local/lib/python3.12/site-packages/elastic_transport/_node/_http_urllib3.py", line 202, in perform_request
    raise err from e
elastic_transport.ConnectionError: Connection error caused by: NewConnectionError(<urllib3.connection.HTTPConnection object at 0x7fbbf4fc9280>: Failed to establish a new connection: [Errno 111] Connection refused)
2025-08-02 15:26:37,767 - elastic_transport.transport - INFO - HEAD http://localhost:9200/ [status:N/A duration:0.000s]
2025-08-02 15:26:37,767 - elastic_transport.node_pool - WARNING - Node <Urllib3HttpNode(http://localhost:9200)> has failed for 6 times in a row, putting on 30 second timeout
2025-08-02 15:26:37,767 - elastic_transport.transport - WARNING - Retrying request after failure (attempt 1 of 3)
Traceback (most recent call last):
  File "/usr/lib/python3/dist-packages/urllib3/connection.py", line 203, in _new_conn
    sock = connection.create_connection(
           ^^^^^^^^^^^^^^^^^^^^^^^^^^^^^
  File "/usr/lib/python3/dist-packages/urllib3/util/connection.py", line 85, in create_connection
    raise err
  File "/usr/lib/python3/dist-packages/urllib3/util/connection.py", line 73, in create_connection
    sock.connect(sa)
ConnectionRefusedError: [Errno 111] Connection refused

The above exception was the direct cause of the following exception:

Traceback (most recent call last):
  File "/home/runner/.local/lib/python3.12/site-packages/elastic_transport/_node/_http_urllib3.py", line 167, in perform_request
    response = self.pool.urlopen(
               ^^^^^^^^^^^^^^^^^^
  File "/usr/lib/python3/dist-packages/urllib3/connectionpool.py", line 845, in urlopen
    retries = retries.increment(
              ^^^^^^^^^^^^^^^^^^
  File "/usr/lib/python3/dist-packages/urllib3/util/retry.py", line 447, in increment
    raise reraise(type(error), error, _stacktrace)
          ^^^^^^^^^^^^^^^^^^^^^^^^^^^^^^^^^^^^^^^^
  File "/usr/lib/python3/dist-packages/urllib3/util/util.py", line 39, in reraise
    raise value
  File "/usr/lib/python3/dist-packages/urllib3/connectionpool.py", line 791, in urlopen
    response = self._make_request(
               ^^^^^^^^^^^^^^^^^^^
  File "/usr/lib/python3/dist-packages/urllib3/connectionpool.py", line 497, in _make_request
    conn.request(
  File "/usr/lib/python3/dist-packages/urllib3/connection.py", line 395, in request
    self.endheaders()
  File "/usr/lib/python3.12/http/client.py", line 1331, in endheaders
    self._send_output(message_body, encode_chunked=encode_chunked)
  File "/usr/lib/python3.12/http/client.py", line 1091, in _send_output
    self.send(msg)
  File "/usr/lib/python3.12/http/client.py", line 1035, in send
    self.connect()
  File "/usr/lib/python3/dist-packages/urllib3/connection.py", line 243, in connect
    self.sock = self._new_conn()
                ^^^^^^^^^^^^^^^^
  File "/usr/lib/python3/dist-packages/urllib3/connection.py", line 218, in _new_conn
    raise NewConnectionError(
urllib3.exceptions.NewConnectionError: <urllib3.connection.HTTPConnection object at 0x7fbbf4fc9b50>: Failed to establish a new connection: [Errno 111] Connection refused

The above exception was the direct cause of the following exception:

Traceback (most recent call last):
  File "/home/runner/.local/lib/python3.12/site-packages/elastic_transport/_transport.py", line 344, in perform_request
    resp = node.perform_request(
           ^^^^^^^^^^^^^^^^^^^^^
  File "/home/runner/.local/lib/python3.12/site-packages/elastic_transport/_node/_http_urllib3.py", line 202, in perform_request
    raise err from e
elastic_transport.ConnectionError: Connection error caused by: NewConnectionError(<urllib3.connection.HTTPConnection object at 0x7fbbf4fc9b50>: Failed to establish a new connection: [Errno 111] Connection refused)
2025-08-02 15:26:37,769 - elastic_transport.transport - INFO - HEAD http://localhost:9200/ [status:N/A duration:0.000s]
2025-08-02 15:26:37,769 - elastic_transport.node_pool - WARNING - Node <Urllib3HttpNode(http://localhost:9200)> has failed for 7 times in a row, putting on 30 second timeout
2025-08-02 15:26:37,769 - elastic_transport.transport - WARNING - Retrying request after failure (attempt 2 of 3)
Traceback (most recent call last):
  File "/usr/lib/python3/dist-packages/urllib3/connection.py", line 203, in _new_conn
    sock = connection.create_connection(
           ^^^^^^^^^^^^^^^^^^^^^^^^^^^^^
  File "/usr/lib/python3/dist-packages/urllib3/util/connection.py", line 85, in create_connection
    raise err
  File "/usr/lib/python3/dist-packages/urllib3/util/connection.py", line 73, in create_connection
    sock.connect(sa)
ConnectionRefusedError: [Errno 111] Connection refused

The above exception was the direct cause of the following exception:

Traceback (most recent call last):
  File "/home/runner/.local/lib/python3.12/site-packages/elastic_transport/_node/_http_urllib3.py", line 167, in perform_request
    response = self.pool.urlopen(
               ^^^^^^^^^^^^^^^^^^
  File "/usr/lib/python3/dist-packages/urllib3/connectionpool.py", line 845, in urlopen
    retries = retries.increment(
              ^^^^^^^^^^^^^^^^^^
  File "/usr/lib/python3/dist-packages/urllib3/util/retry.py", line 447, in increment
    raise reraise(type(error), error, _stacktrace)
          ^^^^^^^^^^^^^^^^^^^^^^^^^^^^^^^^^^^^^^^^
  File "/usr/lib/python3/dist-packages/urllib3/util/util.py", line 39, in reraise
    raise value
  File "/usr/lib/python3/dist-packages/urllib3/connectionpool.py", line 791, in urlopen
    response = self._make_request(
               ^^^^^^^^^^^^^^^^^^^
  File "/usr/lib/python3/dist-packages/urllib3/connectionpool.py", line 497, in _make_request
    conn.request(
  File "/usr/lib/python3/dist-packages/urllib3/connection.py", line 395, in request
    self.endheaders()
  File "/usr/lib/python3.12/http/client.py", line 1331, in endheaders
    self._send_output(message_body, encode_chunked=encode_chunked)
  File "/usr/lib/python3.12/http/client.py", line 1091, in _send_output
    self.send(msg)
  File "/usr/lib/python3.12/http/client.py", line 1035, in send
    self.connect()
  File "/usr/lib/python3/dist-packages/urllib3/connection.py", line 243, in connect
    self.sock = self._new_conn()
                ^^^^^^^^^^^^^^^^
  File "/usr/lib/python3/dist-packages/urllib3/connection.py", line 218, in _new_conn
    raise NewConnectionError(
urllib3.exceptions.NewConnectionError: <urllib3.connection.HTTPConnection object at 0x7fbbf4fc98e0>: Failed to establish a new connection: [Errno 111] Connection refused

The above exception was the direct cause of the following exception:

Traceback (most recent call last):
  File "/home/runner/.local/lib/python3.12/site-packages/elastic_transport/_transport.py", line 344, in perform_request
    resp = node.perform_request(
           ^^^^^^^^^^^^^^^^^^^^^
  File "/home/runner/.local/lib/python3.12/site-packages/elastic_transport/_node/_http_urllib3.py", line 202, in perform_request
    raise err from e
elastic_transport.ConnectionError: Connection error caused by: NewConnectionError(<urllib3.connection.HTTPConnection object at 0x7fbbf4fc98e0>: Failed to establish a new connection: [Errno 111] Connection refused)
2025-08-02 15:26:37,770 - elastic_transport.transport - INFO - HEAD http://localhost:9200/ [status:N/A duration:0.000s]
2025-08-02 15:26:37,770 - elastic_transport.node_pool - WARNING - Node <Urllib3HttpNode(http://localhost:9200)> has failed for 8 times in a row, putting on 30 second timeout
2025-08-02 15:26:37,770 - src.pipeline.pipeline_processor - INFO - ✓ format_detector: OK
2025-08-02 15:26:37,770 - src.pipeline.pipeline_processor - WARNING - ✗ ocr_processor: tesseract is not installed or it's not in your PATH. See README file for more information.
2025-08-02 15:26:37,771 - src.pipeline.pipeline_processor - INFO - ✓ text_extractor: OK
2025-08-02 15:26:37,771 - src.pipeline.pipeline_processor - INFO - ✓ classifier: OK
2025-08-02 15:26:37,771 - src.pipeline.pipeline_processor - WARNING - ✗ elasticsearch: Cannot reach Elasticsearch
2025-08-02 15:26:37,771 - src.pipeline.pipeline_processor - INFO - Setting up default classifier with sample data...
2025-08-02 15:26:37,772 - src.pipeline.classifier - ERROR - Error training model: The test_size = 6 should be greater or equal to the number of classes = 10
2025-08-02 15:26:37,772 - src.pipeline.pipeline_processor - ERROR - Failed to train default classifier: The test_size = 6 should be greater or equal to the number of classes = 10
2025-08-02 15:26:37,772 - src.pipeline.pipeline_processor - INFO - Pipeline system started successfully
2025-08-02 15:26:37,780 - werkzeug - WARNING -  * Debugger is active!
2025-08-02 15:26:37,782 - werkzeug - INFO -  * Debugger PIN: 333-563-054
2025-08-02 15:27:19,900 - src.pipeline.ocr_processor - ERROR - Tesseract installation test failed: tesseract is not installed or it's not in your PATH. See README file for more information.
2025-08-02 15:27:19,900 - elastic_transport.node_pool - INFO - Resurrected node <Urllib3HttpNode(http://localhost:9200)> (force=False)
2025-08-02 15:27:19,901 - elastic_transport.transport - INFO - HEAD http://localhost:9200/ [status:N/A duration:0.001s]
2025-08-02 15:27:19,901 - elastic_transport.node_pool - WARNING - Node <Urllib3HttpNode(http://localhost:9200)> has failed for 9 times in a row, putting on 30 second timeout
2025-08-02 15:27:19,902 - elastic_transport.transport - WARNING - Retrying request after failure (attempt 0 of 3)
Traceback (most recent call last):
  File "/usr/lib/python3/dist-packages/urllib3/connection.py", line 203, in _new_conn
    sock = connection.create_connection(
           ^^^^^^^^^^^^^^^^^^^^^^^^^^^^^
  File "/usr/lib/python3/dist-packages/urllib3/util/connection.py", line 85, in create_connection
    raise err
  File "/usr/lib/python3/dist-packages/urllib3/util/connection.py", line 73, in create_connection
    sock.connect(sa)
ConnectionRefusedError: [Errno 111] Connection refused

The above exception was the direct cause of the following exception:

Traceback (most recent call last):
  File "/home/runner/.local/lib/python3.12/site-packages/elastic_transport/_node/_http_urllib3.py", line 167, in perform_request
    response = self.pool.urlopen(
               ^^^^^^^^^^^^^^^^^^
  File "/usr/lib/python3/dist-packages/urllib3/connectionpool.py", line 845, in urlopen
    retries = retries.increment(
              ^^^^^^^^^^^^^^^^^^
  File "/usr/lib/python3/dist-packages/urllib3/util/retry.py", line 447, in increment
    raise reraise(type(error), error, _stacktrace)
          ^^^^^^^^^^^^^^^^^^^^^^^^^^^^^^^^^^^^^^^^
  File "/usr/lib/python3/dist-packages/urllib3/util/util.py", line 39, in reraise
    raise value
  File "/usr/lib/python3/dist-packages/urllib3/connectionpool.py", line 791, in urlopen
    response = self._make_request(
               ^^^^^^^^^^^^^^^^^^^
  File "/usr/lib/python3/dist-packages/urllib3/connectionpool.py", line 497, in _make_request
    conn.request(
  File "/usr/lib/python3/dist-packages/urllib3/connection.py", line 395, in request
    self.endheaders()
  File "/usr/lib/python3.12/http/client.py", line 1331, in endheaders
    self._send_output(message_body, encode_chunked=encode_chunked)
  File "/usr/lib/python3.12/http/client.py", line 1091, in _send_output
    self.send(msg)
  File "/usr/lib/python3.12/http/client.py", line 1035, in send
    self.connect()
  File "/usr/lib/python3/dist-packages/urllib3/connection.py", line 243, in connect
    self.sock = self._new_conn()
                ^^^^^^^^^^^^^^^^
  File "/usr/lib/python3/dist-packages/urllib3/connection.py", line 218, in _new_conn
    raise NewConnectionError(
urllib3.exceptions.NewConnectionError: <urllib3.connection.HTTPConnection object at 0x7fbbf0cb4ce0>: Failed to establish a new connection: [Errno 111] Connection refused

The above exception was the direct cause of the following exception:

Traceback (most recent call last):
  File "/home/runner/.local/lib/python3.12/site-packages/elastic_transport/_transport.py", line 344, in perform_request
    resp = node.perform_request(
           ^^^^^^^^^^^^^^^^^^^^^
  File "/home/runner/.local/lib/python3.12/site-packages/elastic_transport/_node/_http_urllib3.py", line 202, in perform_request
    raise err from e
elastic_transport.ConnectionError: Connection error caused by: NewConnectionError(<urllib3.connection.HTTPConnection object at 0x7fbbf0cb4ce0>: Failed to establish a new connection: [Errno 111] Connection refused)
2025-08-02 15:27:19,903 - elastic_transport.node_pool - INFO - Resurrected node <Urllib3HttpNode(http://localhost:9200)> (force=False)
2025-08-02 15:27:19,904 - elastic_transport.transport - INFO - HEAD http://localhost:9200/ [status:N/A duration:0.001s]
2025-08-02 15:27:19,904 - elastic_transport.node_pool - WARNING - Node <Urllib3HttpNode(http://localhost:9200)> has failed for 10 times in a row, putting on 30 second timeout
2025-08-02 15:27:19,904 - elastic_transport.transport - WARNING - Retrying request after failure (attempt 1 of 3)
Traceback (most recent call last):
  File "/usr/lib/python3/dist-packages/urllib3/connection.py", line 203, in _new_conn
    sock = connection.create_connection(
           ^^^^^^^^^^^^^^^^^^^^^^^^^^^^^
  File "/usr/lib/python3/dist-packages/urllib3/util/connection.py", line 85, in create_connection
    raise err
  File "/usr/lib/python3/dist-packages/urllib3/util/connection.py", line 73, in create_connection
    sock.connect(sa)
ConnectionRefusedError: [Errno 111] Connection refused

The above exception was the direct cause of the following exception:

Traceback (most recent call last):
  File "/home/runner/.local/lib/python3.12/site-packages/elastic_transport/_node/_http_urllib3.py", line 167, in perform_request
    response = self.pool.urlopen(
               ^^^^^^^^^^^^^^^^^^
  File "/usr/lib/python3/dist-packages/urllib3/connectionpool.py", line 845, in urlopen
    retries = retries.increment(
              ^^^^^^^^^^^^^^^^^^
  File "/usr/lib/python3/dist-packages/urllib3/util/retry.py", line 447, in increment
    raise reraise(type(error), error, _stacktrace)
          ^^^^^^^^^^^^^^^^^^^^^^^^^^^^^^^^^^^^^^^^
  File "/usr/lib/python3/dist-packages/urllib3/util/util.py", line 39, in reraise
    raise value
  File "/usr/lib/python3/dist-packages/urllib3/connectionpool.py", line 791, in urlopen
    response = self._make_request(
               ^^^^^^^^^^^^^^^^^^^
  File "/usr/lib/python3/dist-packages/urllib3/connectionpool.py", line 497, in _make_request
    conn.request(
  File "/usr/lib/python3/dist-packages/urllib3/connection.py", line 395, in request
    self.endheaders()
  File "/usr/lib/python3.12/http/client.py", line 1331, in endheaders
    self._send_output(message_body, encode_chunked=encode_chunked)
  File "/usr/lib/python3.12/http/client.py", line 1091, in _send_output
    self.send(msg)
  File "/usr/lib/python3.12/http/client.py", line 1035, in send
    self.connect()
  File "/usr/lib/python3/dist-packages/urllib3/connection.py", line 243, in connect
    self.sock = self._new_conn()
                ^^^^^^^^^^^^^^^^
  File "/usr/lib/python3/dist-packages/urllib3/connection.py", line 218, in _new_conn
    raise NewConnectionError(
urllib3.exceptions.NewConnectionError: <urllib3.connection.HTTPConnection object at 0x7fbbf1d8c320>: Failed to establish a new connection: [Errno 111] Connection refused

The above exception was the direct cause of the following exception:

Traceback (most recent call last):
  File "/home/runner/.local/lib/python3.12/site-packages/elastic_transport/_transport.py", line 344, in perform_request
    resp = node.perform_request(
           ^^^^^^^^^^^^^^^^^^^^^
  File "/home/runner/.local/lib/python3.12/site-packages/elastic_transport/_node/_http_urllib3.py", line 202, in perform_request
    raise err from e
elastic_transport.ConnectionError: Connection error caused by: NewConnectionError(<urllib3.connection.HTTPConnection object at 0x7fbbf1d8c320>: Failed to establish a new connection: [Errno 111] Connection refused)
2025-08-02 15:27:19,905 - elastic_transport.node_pool - INFO - Resurrected node <Urllib3HttpNode(http://localhost:9200)> (force=False)
2025-08-02 15:27:19,906 - elastic_transport.transport - INFO - HEAD http://localhost:9200/ [status:N/A duration:0.000s]
2025-08-02 15:27:19,906 - elastic_transport.node_pool - WARNING - Node <Urllib3HttpNode(http://localhost:9200)> has failed for 11 times in a row, putting on 30 second timeout
2025-08-02 15:27:19,906 - elastic_transport.transport - WARNING - Retrying request after failure (attempt 2 of 3)
Traceback (most recent call last):
  File "/usr/lib/python3/dist-packages/urllib3/connection.py", line 203, in _new_conn
    sock = connection.create_connection(
           ^^^^^^^^^^^^^^^^^^^^^^^^^^^^^
  File "/usr/lib/python3/dist-packages/urllib3/util/connection.py", line 85, in create_connection
    raise err
  File "/usr/lib/python3/dist-packages/urllib3/util/connection.py", line 73, in create_connection
    sock.connect(sa)
ConnectionRefusedError: [Errno 111] Connection refused

The above exception was the direct cause of the following exception:

Traceback (most recent call last):
  File "/home/runner/.local/lib/python3.12/site-packages/elastic_transport/_node/_http_urllib3.py", line 167, in perform_request
    response = self.pool.urlopen(
               ^^^^^^^^^^^^^^^^^^
  File "/usr/lib/python3/dist-packages/urllib3/connectionpool.py", line 845, in urlopen
    retries = retries.increment(
              ^^^^^^^^^^^^^^^^^^
  File "/usr/lib/python3/dist-packages/urllib3/util/retry.py", line 447, in increment
    raise reraise(type(error), error, _stacktrace)
          ^^^^^^^^^^^^^^^^^^^^^^^^^^^^^^^^^^^^^^^^
  File "/usr/lib/python3/dist-packages/urllib3/util/util.py", line 39, in reraise
    raise value
  File "/usr/lib/python3/dist-packages/urllib3/connectionpool.py", line 791, in urlopen
    response = self._make_request(
               ^^^^^^^^^^^^^^^^^^^
  File "/usr/lib/python3/dist-packages/urllib3/connectionpool.py", line 497, in _make_request
    conn.request(
  File "/usr/lib/python3/dist-packages/urllib3/connection.py", line 395, in request
    self.endheaders()
  File "/usr/lib/python3.12/http/client.py", line 1331, in endheaders
    self._send_output(message_body, encode_chunked=encode_chunked)
  File "/usr/lib/python3.12/http/client.py", line 1091, in _send_output
    self.send(msg)
  File "/usr/lib/python3.12/http/client.py", line 1035, in send
    self.connect()
  File "/usr/lib/python3/dist-packages/urllib3/connection.py", line 243, in connect
    self.sock = self._new_conn()
                ^^^^^^^^^^^^^^^^
  File "/usr/lib/python3/dist-packages/urllib3/connection.py", line 218, in _new_conn
    raise NewConnectionError(
urllib3.exceptions.NewConnectionError: <urllib3.connection.HTTPConnection object at 0x7fbbf1d8c500>: Failed to establish a new connection: [Errno 111] Connection refused

The above exception was the direct cause of the following exception:

Traceback (most recent call last):
  File "/home/runner/.local/lib/python3.12/site-packages/elastic_transport/_transport.py", line 344, in perform_request
    resp = node.perform_request(
           ^^^^^^^^^^^^^^^^^^^^^
  File "/home/runner/.local/lib/python3.12/site-packages/elastic_transport/_node/_http_urllib3.py", line 202, in perform_request
    raise err from e
elastic_transport.ConnectionError: Connection error caused by: NewConnectionError(<urllib3.connection.HTTPConnection object at 0x7fbbf1d8c500>: Failed to establish a new connection: [Errno 111] Connection refused)
2025-08-02 15:27:19,908 - elastic_transport.node_pool - INFO - Resurrected node <Urllib3HttpNode(http://localhost:9200)> (force=False)
2025-08-02 15:27:19,909 - elastic_transport.transport - INFO - HEAD http://localhost:9200/ [status:N/A duration:0.000s]
2025-08-02 15:27:19,909 - elastic_transport.node_pool - WARNING - Node <Urllib3HttpNode(http://localhost:9200)> has failed for 12 times in a row, putting on 30 second timeout
2025-08-02 15:27:19,927 - werkzeug - INFO - 127.0.0.1 - - [02/Aug/2025 15:27:19] "GET / HTTP/1.1" 200 -
2025-08-02 15:27:38,967 - src.pipeline.ocr_processor - ERROR - Tesseract installation test failed: tesseract is not installed or it's not in your PATH. See README file for more information.
2025-08-02 15:27:38,967 - elastic_transport.node_pool - INFO - Resurrected node <Urllib3HttpNode(http://localhost:9200)> (force=False)
2025-08-02 15:27:38,968 - elastic_transport.transport - INFO - HEAD http://localhost:9200/ [status:N/A duration:0.001s]
2025-08-02 15:27:38,969 - elastic_transport.node_pool - WARNING - Node <Urllib3HttpNode(http://localhost:9200)> has failed for 13 times in a row, putting on 30 second timeout
2025-08-02 15:27:38,969 - elastic_transport.transport - WARNING - Retrying request after failure (attempt 0 of 3)
Traceback (most recent call last):
  File "/usr/lib/python3/dist-packages/urllib3/connection.py", line 203, in _new_conn
    sock = connection.create_connection(
           ^^^^^^^^^^^^^^^^^^^^^^^^^^^^^
  File "/usr/lib/python3/dist-packages/urllib3/util/connection.py", line 85, in create_connection
    raise err
  File "/usr/lib/python3/dist-packages/urllib3/util/connection.py", line 73, in create_connection
    sock.connect(sa)
ConnectionRefusedError: [Errno 111] Connection refused

The above exception was the direct cause of the following exception:

Traceback (most recent call last):
  File "/home/runner/.local/lib/python3.12/site-packages/elastic_transport/_node/_http_urllib3.py", line 167, in perform_request
    response = self.pool.urlopen(
               ^^^^^^^^^^^^^^^^^^
  File "/usr/lib/python3/dist-packages/urllib3/connectionpool.py", line 845, in urlopen
    retries = retries.increment(
              ^^^^^^^^^^^^^^^^^^
  File "/usr/lib/python3/dist-packages/urllib3/util/retry.py", line 447, in increment
    raise reraise(type(error), error, _stacktrace)
          ^^^^^^^^^^^^^^^^^^^^^^^^^^^^^^^^^^^^^^^^
  File "/usr/lib/python3/dist-packages/urllib3/util/util.py", line 39, in reraise
    raise value
  File "/usr/lib/python3/dist-packages/urllib3/connectionpool.py", line 791, in urlopen
    response = self._make_request(
               ^^^^^^^^^^^^^^^^^^^
  File "/usr/lib/python3/dist-packages/urllib3/connectionpool.py", line 497, in _make_request
    conn.request(
  File "/usr/lib/python3/dist-packages/urllib3/connection.py", line 395, in request
    self.endheaders()
  File "/usr/lib/python3.12/http/client.py", line 1331, in endheaders
    self._send_output(message_body, encode_chunked=encode_chunked)
  File "/usr/lib/python3.12/http/client.py", line 1091, in _send_output
    self.send(msg)
  File "/usr/lib/python3.12/http/client.py", line 1035, in send
    self.connect()
  File "/usr/lib/python3/dist-packages/urllib3/connection.py", line 243, in connect
    self.sock = self._new_conn()
                ^^^^^^^^^^^^^^^^
  File "/usr/lib/python3/dist-packages/urllib3/connection.py", line 218, in _new_conn
    raise NewConnectionError(
urllib3.exceptions.NewConnectionError: <urllib3.connection.HTTPConnection object at 0x7fbbf1d83a10>: Failed to establish a new connection: [Errno 111] Connection refused

The above exception was the direct cause of the following exception:

Traceback (most recent call last):
  File "/home/runner/.local/lib/python3.12/site-packages/elastic_transport/_transport.py", line 344, in perform_request
    resp = node.perform_request(
           ^^^^^^^^^^^^^^^^^^^^^
  File "/home/runner/.local/lib/python3.12/site-packages/elastic_transport/_node/_http_urllib3.py", line 202, in perform_request
    raise err from e
elastic_transport.ConnectionError: Connection error caused by: NewConnectionError(<urllib3.connection.HTTPConnection object at 0x7fbbf1d83a10>: Failed to establish a new connection: [Errno 111] Connection refused)
2025-08-02 15:27:38,970 - elastic_transport.node_pool - INFO - Resurrected node <Urllib3HttpNode(http://localhost:9200)> (force=False)
2025-08-02 15:27:38,971 - elastic_transport.transport - INFO - HEAD http://localhost:9200/ [status:N/A duration:0.000s]
2025-08-02 15:27:38,971 - elastic_transport.node_pool - WARNING - Node <Urllib3HttpNode(http://localhost:9200)> has failed for 14 times in a row, putting on 30 second timeout
2025-08-02 15:27:38,972 - elastic_transport.transport - WARNING - Retrying request after failure (attempt 1 of 3)
Traceback (most recent call last):
  File "/usr/lib/python3/dist-packages/urllib3/connection.py", line 203, in _new_conn
    sock = connection.create_connection(
           ^^^^^^^^^^^^^^^^^^^^^^^^^^^^^
  File "/usr/lib/python3/dist-packages/urllib3/util/connection.py", line 85, in create_connection
    raise err
  File "/usr/lib/python3/dist-packages/urllib3/util/connection.py", line 73, in create_connection
    sock.connect(sa)
ConnectionRefusedError: [Errno 111] Connection refused

The above exception was the direct cause of the following exception:

Traceback (most recent call last):
  File "/home/runner/.local/lib/python3.12/site-packages/elastic_transport/_node/_http_urllib3.py", line 167, in perform_request
    response = self.pool.urlopen(
               ^^^^^^^^^^^^^^^^^^
  File "/usr/lib/python3/dist-packages/urllib3/connectionpool.py", line 845, in urlopen
    retries = retries.increment(
              ^^^^^^^^^^^^^^^^^^
  File "/usr/lib/python3/dist-packages/urllib3/util/retry.py", line 447, in increment
    raise reraise(type(error), error, _stacktrace)
          ^^^^^^^^^^^^^^^^^^^^^^^^^^^^^^^^^^^^^^^^
  File "/usr/lib/python3/dist-packages/urllib3/util/util.py", line 39, in reraise
    raise value
  File "/usr/lib/python3/dist-packages/urllib3/connectionpool.py", line 791, in urlopen
    response = self._make_request(
               ^^^^^^^^^^^^^^^^^^^
  File "/usr/lib/python3/dist-packages/urllib3/connectionpool.py", line 497, in _make_request
    conn.request(
  File "/usr/lib/python3/dist-packages/urllib3/connection.py", line 395, in request
    self.endheaders()
  File "/usr/lib/python3.12/http/client.py", line 1331, in endheaders
    self._send_output(message_body, encode_chunked=encode_chunked)
  File "/usr/lib/python3.12/http/client.py", line 1091, in _send_output
    self.send(msg)
  File "/usr/lib/python3.12/http/client.py", line 1035, in send
    self.connect()
  File "/usr/lib/python3/dist-packages/urllib3/connection.py", line 243, in connect
    self.sock = self._new_conn()
                ^^^^^^^^^^^^^^^^
  File "/usr/lib/python3/dist-packages/urllib3/connection.py", line 218, in _new_conn
    raise NewConnectionError(
urllib3.exceptions.NewConnectionError: <urllib3.connection.HTTPConnection object at 0x7fbbf1d821e0>: Failed to establish a new connection: [Errno 111] Connection refused

The above exception was the direct cause of the following exception:

Traceback (most recent call last):
  File "/home/runner/.local/lib/python3.12/site-packages/elastic_transport/_transport.py", line 344, in perform_request
    resp = node.perform_request(
           ^^^^^^^^^^^^^^^^^^^^^
  File "/home/runner/.local/lib/python3.12/site-packages/elastic_transport/_node/_http_urllib3.py", line 202, in perform_request
    raise err from e
elastic_transport.ConnectionError: Connection error caused by: NewConnectionError(<urllib3.connection.HTTPConnection object at 0x7fbbf1d821e0>: Failed to establish a new connection: [Errno 111] Connection refused)
2025-08-02 15:27:38,973 - elastic_transport.node_pool - INFO - Resurrected node <Urllib3HttpNode(http://localhost:9200)> (force=False)
2025-08-02 15:27:38,974 - elastic_transport.transport - INFO - HEAD http://localhost:9200/ [status:N/A duration:0.000s]
2025-08-02 15:27:38,974 - elastic_transport.node_pool - WARNING - Node <Urllib3HttpNode(http://localhost:9200)> has failed for 15 times in a row, putting on 30 second timeout
2025-08-02 15:27:38,975 - elastic_transport.transport - WARNING - Retrying request after failure (attempt 2 of 3)
Traceback (most recent call last):
  File "/usr/lib/python3/dist-packages/urllib3/connection.py", line 203, in _new_conn
    sock = connection.create_connection(
           ^^^^^^^^^^^^^^^^^^^^^^^^^^^^^
  File "/usr/lib/python3/dist-packages/urllib3/util/connection.py", line 85, in create_connection
    raise err
  File "/usr/lib/python3/dist-packages/urllib3/util/connection.py", line 73, in create_connection
    sock.connect(sa)
ConnectionRefusedError: [Errno 111] Connection refused

The above exception was the direct cause of the following exception:

Traceback (most recent call last):
  File "/home/runner/.local/lib/python3.12/site-packages/elastic_transport/_node/_http_urllib3.py", line 167, in perform_request
    response = self.pool.urlopen(
               ^^^^^^^^^^^^^^^^^^
  File "/usr/lib/python3/dist-packages/urllib3/connectionpool.py", line 845, in urlopen
    retries = retries.increment(
              ^^^^^^^^^^^^^^^^^^
  File "/usr/lib/python3/dist-packages/urllib3/util/retry.py", line 447, in increment
    raise reraise(type(error), error, _stacktrace)
          ^^^^^^^^^^^^^^^^^^^^^^^^^^^^^^^^^^^^^^^^
  File "/usr/lib/python3/dist-packages/urllib3/util/util.py", line 39, in reraise
    raise value
  File "/usr/lib/python3/dist-packages/urllib3/connectionpool.py", line 791, in urlopen
    response = self._make_request(
               ^^^^^^^^^^^^^^^^^^^
  File "/usr/lib/python3/dist-packages/urllib3/connectionpool.py", line 497, in _make_request
    conn.request(
  File "/usr/lib/python3/dist-packages/urllib3/connection.py", line 395, in request
    self.endheaders()
  File "/usr/lib/python3.12/http/client.py", line 1331, in endheaders
    self._send_output(message_body, encode_chunked=encode_chunked)
  File "/usr/lib/python3.12/http/client.py", line 1091, in _send_output
    self.send(msg)
  File "/usr/lib/python3.12/http/client.py", line 1035, in send
    self.connect()
  File "/usr/lib/python3/dist-packages/urllib3/connection.py", line 243, in connect
    self.sock = self._new_conn()
                ^^^^^^^^^^^^^^^^
  File "/usr/lib/python3/dist-packages/urllib3/connection.py", line 218, in _new_conn
    raise NewConnectionError(
urllib3.exceptions.NewConnectionError: <urllib3.connection.HTTPConnection object at 0x7fbbf1d82450>: Failed to establish a new connection: [Errno 111] Connection refused

The above exception was the direct cause of the following exception:

Traceback (most recent call last):
  File "/home/runner/.local/lib/python3.12/site-packages/elastic_transport/_transport.py", line 344, in perform_request
    resp = node.perform_request(
           ^^^^^^^^^^^^^^^^^^^^^
  File "/home/runner/.local/lib/python3.12/site-packages/elastic_transport/_node/_http_urllib3.py", line 202, in perform_request
    raise err from e
elastic_transport.ConnectionError: Connection error caused by: NewConnectionError(<urllib3.connection.HTTPConnection object at 0x7fbbf1d82450>: Failed to establish a new connection: [Errno 111] Connection refused)
2025-08-02 15:27:38,976 - elastic_transport.node_pool - INFO - Resurrected node <Urllib3HttpNode(http://localhost:9200)> (force=False)
2025-08-02 15:27:38,977 - elastic_transport.transport - INFO - HEAD http://localhost:9200/ [status:N/A duration:0.000s]
2025-08-02 15:27:38,977 - elastic_transport.node_pool - WARNING - Node <Urllib3HttpNode(http://localhost:9200)> has failed for 16 times in a row, putting on 30 second timeout
2025-08-02 15:27:38,978 - werkzeug - INFO - 127.0.0.1 - - [02/Aug/2025 15:27:38] "GET / HTTP/1.1" 200 -
2025-08-02 15:27:39,048 - werkzeug - INFO - 127.0.0.1 - - [02/Aug/2025 15:27:39] "GET /static/css/main.css HTTP/1.1" 200 -
2025-08-02 15:27:39,052 - werkzeug - INFO - 127.0.0.1 - - [02/Aug/2025 15:27:39] "GET /static/js/main.js HTTP/1.1" 200 -
2025-08-02 15:28:05,966 - werkzeug - INFO - 127.0.0.1 - - [02/Aug/2025 15:28:05] "GET /models HTTP/1.1" 200 -
2025-08-02 15:28:05,995 - werkzeug - INFO - 127.0.0.1 - - [02/Aug/2025 15:28:05] "GET /static/css/main.css HTTP/1.1" 200 -
2025-08-02 15:28:06,001 - werkzeug - INFO - 127.0.0.1 - - [02/Aug/2025 15:28:06] "GET /static/js/main.js HTTP/1.1" 200 -
2025-08-02 15:28:18,019 - werkzeug - INFO - 127.0.0.1 - - [02/Aug/2025 15:28:18] "GET /settings HTTP/1.1" 200 -
2025-08-02 15:28:18,037 - werkzeug - INFO - 127.0.0.1 - - [02/Aug/2025 15:28:18] "GET /static/css/main.css HTTP/1.1" 200 -
2025-08-02 15:28:18,046 - werkzeug - INFO - 127.0.0.1 - - [02/Aug/2025 15:28:18] "GET /static/js/main.js HTTP/1.1" 200 -
